Workbook

Sheet xe
A1: MA | B1: SỐ XE
A3: B Tâm | B3: 50H-70216
A4: T LUÂN | B4: 50H-55116
A5: Y THANH | B5: 50H-69501
A6: Q HẢI | B6: 50H-64316
A7: D PHÚ | B7: 50H-50999
A8: Ư LỪA | B8: 50H-63174
A9: V LUÂN | B9: 50H-64470
A10: F SƠN | B10: 50H-54580
A11: F Y | B11: 50H-54580
A12: g nhanh | B12: 51H -88294
A13: N THUẬN | B13: 50H-66445
... A50: T T | B50: 85H-01932

Sheet ma
A1: MA | B1: TUYEN | C1: OTO 5
A2: NT | B2: NHA TRANG
A3: NHOA | B3: NINH HÒA
A4: CR | B4: CAM RANH
A5: CLANH | B5: CAO LÃNH | C5: 280000
A6: LKX | B6: LONG KHÁNH XÁ | C6: 244000
A7: LKP | B7: LONG KHÁNH PALLET | C7: 244000
A9: AJLH | B9: AJ LONG HẬU | C9: 600000
A10: ndfc | B10: Chuyển Hàng ndfc | C10: 410000
A11: N6 | B11: NDFC 6 CHUYẾN | C11: 300000
A12: calo | B12: Chuyển hàng Calofic | C12: 180000
A13: CL1 | B13: CH Calofic 13c | C13: 140000
A14: clun | B14: CALOFIC - UNI ( xe nhỏ ) | C14: 300000
A15: cluni | B15: CALOFIC - UNI ( xe lớn ) | C15: 400000
A16: CLMXL | B16: COOP LÊ MINH XUÂN ( XE LỚN ) | C16: 200000
A17: UNCLG | B17: UNI - CALOFIC ( CHUYỂN GẠO ) | C17: 100000
... A46: TP2 | B46: TP2 GÒ VẤP | C46: 800000
A47: NL | B47: NGỌC LAN L.AN
A48: THTDH | B48: TÂN HÙNG THÁI ĐỨC HOÀ | C48: 210000
A49: KVBC | B49: KIẾN VƯƠNG BÌNH CHÁNH | C49: 190000
A50: mifa | B50: MIFA TÂN TẠO | C50: 200000
A51: mf | B51: MIFA TÂN TẠO XE NHỎ ( KBX ) | C51: 800000
A52: BP | B52: BÌNH PHƯỚC
A53: BT | B53: BÌNH TRÍ | C53: 212000
A54: MKR | B54: MAKARA | C54: 200000
A55: TN | B55: TÂY NINH
A56: VL | B56: PHÔI VIỆT LONG
A57: SD | B57: SA ĐÉC
A58: TNOTX | B58: THỐT NỐT XÁ | C58: 370000
A59: CD | B59: CHÂU ĐỐC
A60: HG | B60: HẬU GAING
A61: HT | B61: HÀ TIÊN
A62: PQ | B62: PHÚ QUỐC
A63: NE3 | B63: NESTLE 3-7 | C63: 442000
A64: NE7 | B64: NESTLE 7-10 | C64: 393000
A65: NE10 | B65: NESTLE >10 | C65: 363000
A66: NDNA | B66: NDFC - NAIC BẾN LỨC | C66: 2400000
A67: NAUN | B67: NAIC -UNI | C67: 2400000
A68: nta | B68: NHẬT TRÚC ANH TRẢNG BOM | C68: 240000
A69: TCLA | B69: TRUE CARE LONG AN | C69: 220000
...

Sheet XE NHỎ
D1: CÔNG TNHH DV VT PHÚ PHÁT
D2: 165 Đỗ Thị Lời, P11, Q3, TP. HCM.
D3: cônG TNHH DV VT PHÚ PHÁT
D4: 45961 | Q4: LƯU
D5: Tên : | J5: Số xe :
K6: P | P6: #N/A
A7: F | B7: TÊN | D7: Ngày | E7: Số xe | F7: Nơi giao | H7: Cđường | I7: Cđường | J7: ghi chú | K7: TẤN | L7: B.XẾP | M7: C.phí | N7: ghi chú | O7: TÀI | P7: Đơn giá | Q7: Thành tiền
A8: 10 | B8: hl | C8: z | D8: 46146 | E8: =VLOOKUP($C8,[1]xe!$A:$B,2,0) -> 50H-44024 | F8: =VLOOKUP($B8,[1]ma!$A:$B,2,0) -> HÂN LÊ HÓC MÔN | G8: 71329 | H8: 11/5 | K8: 2 | L8: =K8*50000 -> 100000 | O8: 1 | P8: =VLOOKUP($B8,[1]ma!$A:$C,3,0) -> 800000 | Q8: 880000 | R8: 0.1
A9: 1 | B9: EM | C9: P VŨ | D9: 46083 | E9: =VLOOKUP($C9,xe!$A:$B,2,0) -> 50H-60635 | F9: =VLOOKUP($B9,ma!$A:$B,2,0) -> E MART GÒ VẤP | G9: 35462 | H9: 5/3 | J9: UNI | K9: 1.6 | L9: =K9*50000 -> 80000 | O9: 1 | P9: =VLOOKUP($B9,ma!$A:$C,3,0) -> 800000 | Q9: =VLOOKUP($B9,ma!$A:$C,3,0) -> 800000
A10: =A9+1 -> 2 | B10: EM | C10: Y1 | D10: 46083 | E10: =VLOOKUP($C10,xe!$A:$B,2,0) -> 50H-55829 | F10: =VLOOKUP($B10,ma!$A:$B,2,0) -> E MART GÒ VẤP | G10: 35478+35475 | H10: 5/3 | J10: UNI | K10: 1.6 | L10: =K10*50000 -> 80000 | O10: 1 | P10: =VLOOKUP($B10,ma!$A:$C,3,0) -> 800000 | Q10: =VLOOKUP($B10,ma!$A:$C,3,0) -> 800000
A11: =A10+1 -> 3 | B11: EM | C11: I THI | D11: 46083 | E11: =VLOOKUP($C11,xe!$A:$B,2,0) -> 50H-86564 | F11: =VLOOKUP($B11,ma!$A:$B,2,0) -> E MART GÒ VẤP | G11: 35457 | H11: 5/3 | J11: UNI | K11: 1.6 | L11: =K11*50000 -> 80000 | O11: 1 | P11: =VLOOKUP($B11,ma!$A:$C,3,0) -> 800000 | Q11: =VLOOKUP($B11,ma!$A:$C,3,0) -> 800000
A12: =A11+1 -> 4 | B12: MTAP | C12: X1 | D12: 46083 | E12: =VLOOKUP($C12,xe!$A:$B,2,0) -> 51C-81056 | F12: =VLOOKUP($B12,ma!$A:$B,2,0) -> M. AN PHÚ | G12: pgh | H12: 3/3 | J12: GAO UNI | K12: 2 | L12: =K12*50000 -> 100000 | O12: 1 | P12: =VLOOKUP($B12,ma!$A:$C,3,0) -> 800000 | Q12: =VLOOKUP($B12,ma!$A:$C,3,0) -> 800000
A13: =A12+1 -> 5 | B13: MTAP | C13: X2 | D13: 46083 | E13: =VLOOKUP($C13,xe!$A:$B,2,0) -> 50H-11822 | F13: =VLOOKUP($B13,ma!$A:$B,2,0) -> M. AN PHÚ | G13: pgh | H13: 3/3 | J13: GAO UNI | K13: 2 | L13: =K13*50000 -> 100000 | O13: 1 | P13: =VLOOKUP($B13,ma!$A:$C,3,0) -> 800000 | Q13: =VLOOKUP($B13,ma!$A:$C,3,0) -> 800000
A14: =A13+1 -> 6 | B14: STVT | C14: E1 | D14: 46083 | E14: =VLOOKUP($C14,xe!$A:$B,2,0) -> 51D-38021 | F14: =VLOOKUP($B14,ma!$A:$B,2,0) -> SATRA VIETTEL | G14: 35736+35734+35740+35742+35745 | H14: 5/3 | J14: SX 50H 64316 | K14: 1 | L14: =K14*50000 -> 50000 | O14: 1 | P14: 200000 | Q14: 200000
A15: =A14+1 -> 7 | B15: STVT | C15: Q HẢI | D15: 46083 | E15: =VLOOKUP($C15,xe!$A:$B,2,0) -> 50H-64316 | F15: =VLOOKUP($B15,ma!$A:$B,2,0) -> SATRA VIETTEL | G15: R | H15: R | J15: 51D 38021 SX | K15: 2.2 | L15: =K15*50000 -> 110000 | O15: 1 | P15: =VLOOKUP($B15,ma!$A:$C,3,0) -> 800000 | Q15: =VLOOKUP($B15,ma!$A:$C,3,0) -> 800000
A16: =A14+1 -> 7 | B16: STVT | C16: E | D16: 46083 | E16: =VLOOKUP($C16,xe!$A:$B,2,0) -> 47H-02023 | F16: =VLOOKUP($B16,ma!$A:$B,2,0) -> SATRA VIETTEL | G16: 35654 | H16: 3/3 | K16: 2.2 | L16: =K16*50000 -> 110000 | O16: 1 | P16: =VLOOKUP($B16,ma!$A:$C,3,0) -> 800000 | Q16: =VLOOKUP($B16,ma!$A:$C,3,0) -> 800000
A17: =A16+1 -> 8 | B17: KFC | C17: U THANH | D17: 46083 | E17: =VLOOKUP($C17,xe!$A:$B,2,0) -> 50H-92136 | F17: =VLOOKUP($B17,ma!$A:$B,2,0) -> KFC GÒ VẤP ( K BX ) | G17: 35497 | H17: 3/3 | J17: NDFC | K17: 2 | L17: 100000 | N17: BX | O17: 1 | P17: =VLOOKUP($B17,ma!$A:$C,3,0) -> 800000 | Q17: =VLOOKUP($B17,ma!$A:$C,3,0) -> 800000
A18: =A17+1 -> 9 | B18: KFC | C18: X4 | D18: 46083 | E18: =VLOOKUP($C18,xe!$A:$B,2,0) -> 62H-01887 | F18: =VLOOKUP($B18,ma!$A:$B,2,0) -> KFC GÒ VẤP ( K BX ) | G18: 35513 | H18: 3/3 | J18: NDFC | K18: 2 | L18: =K18*50000 -> 100000 | N18: BX | O18: 1 | P18: =VLOOKUP($B18,ma!$A:$C,3,0) -> 800000 | Q18: =VLOOKUP($B18,ma!$A:$C,3,0) -> 800000
A19: =A18+1 -> 10 | B19: KFC | C19: C THẠCH | D19: 46083 | E19: =VLOOKUP($C19,xe!$A:$B,2,0) -> 50H-74619 | F19: =VLOOKUP($B19,ma!$A:$B,2,0) -> KFC GÒ VẤP ( K BX ) | G19: 35505 | H19: 3/3 | J19: NDFC | K19: 2 | L19: =K19*50000 -> 100000 | N19: BX | O19: 1 | P19: =VLOOKUP($B19,ma!$A:$C,3,0) -> 800000 | Q19: =VLOOKUP($B19,ma!$A:$C,3,0) -> 800000
A20: =A19+1 -> 11 | B20: KFC | C20: A LỢI | D20: 46083 | E20: =VLOOKUP($C20,xe!$A:$B,2,0) -> 50H 87442 | F20: =VLOOKUP($B20,ma!$A:$B,2,0) -> KFC GÒ VẤP ( K BX ) | G20: 35499 | H20: 3/3 | J20: NDFC | K20: 2 | L20: =K20*50000 -> 100000 | N20: BX | O20: 1 | P20: =VLOOKUP($B20,ma!$A:$C,3,0) -> 800000 | Q20: =VLOOKUP($B20,ma!$A:$C,3,0) -> 800000
A21: =A20+1 -> 12 | B21: SSG | C21: LONG | D21: 46083 | E21: =VLOOKUP($C21,xe!$A:$B,2,0) -> 50H-55443 | F21: =VLOOKUP($B21,ma!$A:$B,2,0) -> SATRA SÀI GÒN | G21: 35510 | H21: 3/3 | K21: 2 | L21: =K21*50000 -> 100000 | O21: 1 | P21: =VLOOKUP($B21,ma!$A:$C,3,0) -> 800000 | Q21: =VLOOKUP($B21,ma!$A:$C,3,0) -> 800000
A22: =A21+1 -> 13 | B22: SSG | C22: N THUẬN | D22: 46083 | E22: =VLOOKUP($C22,xe!$A:$B,2,0) -> 50H-66445 | F22: =VLOOKUP($B22,ma!$A:$B,2,0) -> SATRA SÀI GÒN | G22: 35506+35508+35507 | H22: 3/3 | K22: 2.2 | L22: =K22*50000 -> 110000 | O22: 1 | P22: =VLOOKUP($B22,ma!$A:$C,3,0) -> 800000 | Q22: =VLOOKUP($B22,ma!$A:$C,3,0) -> 800000
A23: =A22+1 -> 14 | B23: SSG | C23: Q HẢI | D23: 46083 | E23: =VLOOKUP($C23,xe!$A:$B,2,0) -> 50H-64316 | F23: =VLOOKUP($B23,ma!$A:$B,2,0) -> SATRA SÀI GÒN | G23: 35571 | H23: 3/3 | K23: 2 | L23: =K23*50000 -> 100000 | M23: 30000 | N23: cơm | O23: 1 | P23: =VLOOKUP($B23,ma!$A:$C,3,0) -> 800000 | Q23: =VLOOKUP($B23,ma!$A:$C,3,0) -> 800000
A24: =A23+1 -> 15 | B24: SSG | C24: Ư LỪA | D24: 46083 | E24: =VLOOKUP($C24,xe!$A:$B,2,0) -> 50H-63174 | F24: =VLOOKUP($B24,ma!$A:$B,2,0) -> SATRA SÀI GÒN | G24: 35511+35516+35519 | H24: 3/3 | J24: GHÉP VVK | K24: 2 | L24: =K24*50000 -> 100000 | O24: 1 | P24: =VLOOKUP($B24,ma!$A:$C,3,0) -> 800000 | Q24: =VLOOKUP($B24,ma!$A:$C,3,0) -> 800000
A25: =A24+1 -> 16 | B25: KFC | C25: R THI | D25: 46083 | E25: =VLOOKUP($C25,xe!$A:$B,2,0) -> 50H-55161 | F25: =VLOOKUP($B25,ma!$A:$B,2,0) -> KFC GÒ VẤP ( K BX ) | G25: 35568 | H25: 3/3 | K25: 2 | L25: 50000 | M25: 50000 | N25: bx | O25: 1 | P25: =VLOOKUP($B25,ma!$A:$C,3,0) -> 800000 | Q25: =VLOOKUP($B25,ma!$A:$C,3,0) -> 800000
A26: =A25+1 -> 17 | B26: KFC | C26: A DUNG | D26: 46083 | E26: =VLOOKUP($C26,xe!$A:$B,2,0) -> 50E-565,21 | F26: =VLOOKUP($B26,ma!$A:$B,2,0) -> KFC GÒ VẤP ( K BX ) | G26: 35466 | H26: 3/3 | K26: 2.2 | O26: 1 | P26: =VLOOKUP($B26,ma!$A:$C,3,0) -> 800000 | Q26: =VLOOKUP($B26,ma!$A:$C,3,0) -> 800000
A27: =A26+1 -> 18 | B27: KFC | C27: Y THANH | D27: 46083 | E27: =VLOOKUP($C27,xe!$A:$B,2,0) -> 50H-69501 | F27: =VLOOKUP($B27,ma!$A:$B,2,0) -> KFC GÒ VẤP ( K BX ) | G27: 35465 | H27: 3/3 | K27: 2.2 | L27: 50000 | M27: 20000 | N27: xn | O27: 1 | P27: =VLOOKUP($B27,ma!$A:$C,3,0) -> 800000 | Q27: =VLOOKUP($B27,ma!$A:$C,3,0) -> 800000
A28: =A27+1 -> 19 | B28: KFC | C28: F SƠN | D28: 46083 | E28: =VLOOKUP($C28,xe!$A:$B,2,0) -> 50H-54580 | F28: =VLOOKUP($B28,ma!$A:$B,2,0) -> KFC GÒ VẤP ( K BX ) | G28: 35463 | H28: 3/3 | K28: 2.2 | L28: 50000 | M28: 20000 | N28: bx | O28: 1 | P28: =VLOOKUP($B28,ma!$A:$C,3,0) -> 800000 | Q28: =VLOOKUP($B28,ma!$A:$C,3,0) -> 800000
A29: =A28+1 -> 20 | B29: NTRU | C29: B TÂM | D29: 46083 | E29: =VLOOKUP($C29,xe!$A:$B,2,0) -> 50H-70216 | F29: =VLOOKUP($B29,ma!$A:$B,2,0) -> NGUYỄN TRƯƠNG | G29: 35501+35503 | H29: 3/3 | K29: 2.2 | L29: =K29*50000 -> 110000 | O29: 1 | P29: =VLOOKUP($B29,ma!$A:$C,3,0) -> 800000 | Q29: =VLOOKUP($B29,ma!$A:$C,3,0) -> 800000
A30: =A29+1 -> 21 | B30: TAB | C30: D PHÚ | D30: 46083 | E30: =VLOOKUP($C30,xe!$A:$B,2,0) -> 50H-50999 | F30: =VLOOKUP($B30,ma!$A:$B,2,0) -> TA BAKER Q,12 | G30: 35592 | H30: 5/3 | K30: 1.4 | L30: =K30*50000 -> 70000 | O30: 1 | P30: =VLOOKUP($B30,ma!$A:$C,3,0) -> 800000 | Q30: =VLOOKUP($B30,ma!$A:$C,3,0) -> 800000
A31: =A30+1 -> 22 | B31: TAB | C31: V LUÂN | D31: 46083 | E31: =VLOOKUP($C31,xe!$A:$B,2,0) -> 50H-64470 | F31: =VLOOKUP($B31,ma!$A:$B,2,0) -> TA BAKER Q,12 | G31: 3495+35495 | H31: 5/3 | K31: 1.4 | L31: =K31*50000 -> 70000 | O31: 1 | P31: =VLOOKUP($B31,ma!$A:$C,3,0) -> 800000 | Q31: =VLOOKUP($B31,ma!$A:$C,3,0) -> 800000
A32: =A31+1 -> 23 | B32: MNVT | C32: T LUÂN | D32: 46083 | E32: =VLOOKUP($C32,xe!$A:$B,2,0) -> 50H-55116 | F32: =VLOOKUP($B32,ma!$A:$B,2,0) -> MN VĨNH THẠNH | G32: 35584+35581 | H32: 3/3 | K32: 1 | L32: =K32*50000 -> 50000 | O32: 1 | P32: =VLOOKUP($B32,ma!$A:$C,3,0) -> 800000 | Q32: =VLOOKUP($B32,ma!$A:$C,3,0) -> 800000
A33: =A32+1 -> 24 | B33: SPM | C33: V LUÂN | D33: 46083 | E33: =VLOOKUP($C33,xe!$A:$B,2,0) -> 50H-64470 | F33: =VLOOKUP($B33,ma!$A:$B,2,0) -> SPM TÂN TẠO | G33: 35754 | H33: 5/3 | I33: 10000 | K33: 1.2 | L33: =K33*50000 -> 60000 | M33: 30000 | N33: cơm | O33: 1 | P33: =VLOOKUP($B33,ma!$A:$C,3,0) -> 800000 | Q33: =VLOOKUP($B33,ma!$A:$C,3,0) -> 800000
A34: =A33+1 -> 25 | B34: VHQ8 | C34: G NHANH | D34: 46083 | E34: =VLOOKUP($C34,xe!$A:$B,2,0) -> 51H -88294 | F34: =VLOOKUP($B34,ma!$A:$B,2,0) -> VĂN HẬU Q8 ( K BX ) | G34: R | H34: R | J34: GIAO BƯU LONG | K34: 2.2 | L34: 200000 | N34: BX | O34: 1 | P34: =VLOOKUP($B34,ma!$A:$C,3,0) -> 800000 | Q34: =VLOOKUP($B34,ma!$A:$C,3,0) -> 800000
A35: =A34+1 -> 26 | B35: AF | C35: F SƠN | D35: 46083 | E35: =VLOOKUP($C35,xe!$A:$B,2,0) -> 50H-54580 | F35: =VLOOKUP($B35,ma!$A:$B,2,0) -> ANFOOD Q12 ( K BX ) | G35: 35923 | H35: 4/3 | K35: 2 | L35: 50000 | M35: 30000 | N35: cơm | O35: 1 | P35: =VLOOKUP($B35,ma!$A:$C,3,0) -> 800000 | Q35: =VLOOKUP($B35,ma!$A:$C,3,0) -> 800000
A36: =A35+1 -> 27 | B36: BHCD | C36: R THI | D36: 46083 | E36: =VLOOKUP($C36,xe!$A:$B,2,0) -> 50H-55161 | F36: =VLOOKUP($B36,ma!$A:$B,2,0) -> BHX CẦN ĐƯỚC | G36: 35996 | H36: 3/3 | K36: 2 | L36: 250000 | O36: 1 | P36: =VLOOKUP($B36,ma!$A:$C,3,0) -> 900000 | Q36: =VLOOKUP($B36,ma!$A:$C,3,0) -> 900000
A37: =A36+1 -> 28 | B37: BHCD | C37: C THẠCH | D37: 46083 | E37: =VLOOKUP($C37,xe!$A:$B,2,0) -> 50H-74619 | F37: =VLOOKUP($B37,ma!$A:$B,2,0) -> BHX CẦN ĐƯỚC | G37: 36000 | H37: 3/3 | K37: 2 | L37: 210000 | M37: 30000 | N37: cơm | O37: 1 | P37: =VLOOKUP($B37,ma!$A:$C,3,0) -> 900000 | Q37: =VLOOKUP($B37,ma!$A:$C,3,0) -> 900000
A38: =A37+1 -> 29 | B38: BXA | C38: A DUNG | D38: 46083 | E38: =VLOOKUP($C38,xe!$A:$B,2,0) -> 50E-565,21 | F38: =VLOOKUP($B38,ma!$A:$B,2,0) -> BHX XUYÊN Á | G38: 35969+3740 | H38: 5/3 | K38: 1.2 | L38: =K38*80000 -> 96000 | O38: 1 | P38: =VLOOKUP($B38,ma!$A:$C,3,0) -> 900000 | Q38: =VLOOKUP($B38,ma!$A:$C,3,0) -> 900000
A39: =A38+1 -> 30 | B39: BTDN | C39: Z | D39: 46083 | E39: =VLOOKUP($C39,xe!$A:$B,2,0) -> 50H-44024 | F39: =VLOOKUP($B39,ma!$A:$B,2,0) -> BHX ( TĐN) | G39: 35917+3739 | H39: 6/3 | K39: 1.8 | L39: =K39*80000 -> 144000 | O39: 1 | P39: =VLOOKUP($B39,ma!$A:$C,3,0) -> 800000 | Q39: =VLOOKUP($B39,ma!$A:$C,3,0) -> 800000
A40: =A39+1 -> 31 | B40: BNB | C40: T LUÂN | D40: 46083 | E40: =VLOOKUP($C40,xe!$A:$B,2,0) -> 50H-55116 | F40: =VLOOKUP($B40,ma!$A:$B,2,0) -> BHX NHÀ BÈ | G40: 3738+35893 | H40: 3/3 | K40: 1.6 | L40: =K40*50000 -> 80000 | O40: 1 | P40: =VLOOKUP($B40,ma!$A:$C,3,0) -> 400000 | Q40: =VLOOKUP($B40,ma!$A:$C,3,0) -> 400000
...

Sheet XE LỚN
D1: KÊ CHI TIẾT XE LỚN
D2: 46054
D3: Tên : | G3: SỐ XE :
F4: #N/A | K4: 2 | L4: 2 | N4: #N/A
A5: STT | B5: Mã | C5: Tên TX | D5: Ngày | E5: Số Xe | F5: Nơi giao | G5: Đổ Dầu | H5: SỐ KM | I5: C.Phí lấy hàng | J5: ghi chú | K5: C.phí tài xế | L5: ghi chú | M5: TÀI | N5: Đơn giá | O5: Thành tiền | P5: LƯƠNG LX
A6: 1 | B6: MIFA | C6: L1 THÀNH | D6: 46083 | E6: =VLOOKUP($C6,xe!$A:$B,2,0) -> 50E-648.73 | F6: =VLOOKUP($B6,ma!$A:$B,2,0) -> MIFA TÂN TẠO | I6: 200000 | K6: 20000 | L6: nvl | M6: 13.54 | N6: =VLOOKUP($B6,ma!$A:$C,3,0) -> 200000 | O6: =M6*N6 -> 2708000 | P6: =O6*10% -> 270800
A7: =A6+1 -> 2 | B7: GHTGP | C7: L2 HOÀI | D7: 46083 | E7: =VLOOKUP($C7,xe!$A:$B,2,0) -> 50H-66347 | F7: =VLOOKUP($B7,ma!$A:$B,2,0) -> GIA HOÀNG TIỀN GIANG PALLET | I7: 200000 | J7: bx | K7: 150000 | L7: bao gạo | M7: 18.5 | N7: =VLOOKUP($B7,ma!$A:$C,3,0) -> 230000 | O7: =M7*N7 -> 4255000 | P7: =O7*10% -> 425500
A8: =A7+1 -> 3 | B8: NDNA | C8: L2 HOÀI | D8: 46083 | E8: =VLOOKUP($C8,xe!$A:$B,2,0) -> 50H-66347 | F8: =VLOOKUP($B8,ma!$A:$B,2,0) -> NDFC - NAIC BẾN LỨC | I8: 100000 | J8: bx | M8: 1 | N8: =VLOOKUP($B8,ma!$A:$C,3,0) -> 2400000 | O8: =M8*N8 -> 2400000 | P8: =O8*10% -> 240000
A9: =A8+1 -> 4 | B9: TLP | C9: L3 MẾN | D9: 46083 | E9: =VLOOKUP($C9,xe!$A:$B,2,0) -> 50E-654.34 | F9: =VLOOKUP($B9,ma!$A:$B,2,0) -> TUẤN LỘC Q7 PALLET | I9: 100000 | J9: bx | M9: 13.5 | N9: =VLOOKUP($B9,ma!$A:$C,3,0) -> 200000 | O9: =M9*N9 -> 2700000 | P9: =O9*10% -> 270000
A10: =A9+1 -> 5 | B10: NDNA | C10: L3 MẾN | D10: 46083 | E10: =VLOOKUP($C10,xe!$A:$B,2,0) -> 50E-654.34 | F10: =VLOOKUP($B10,ma!$A:$B,2,0) -> NDFC - NAIC BẾN LỨC | I10: 100000 | J10: bx | M10: 1 | N10: =VLOOKUP($B10,ma!$A:$C,3,0) -> 2400000 | O10: =M10*N10 -> 2400000 | P10: =O10*10% -> 240000
A11: =A10+1 -> 6 | B11: TLP | C11: L4 HOÀ | D11: 46083 | E11: =VLOOKUP($C11,xe!$A:$B,2,0) -> 50E-324,01 | F11: =VLOOKUP($B11,ma!$A:$B,2,0) -> TUẤN LỘC Q7 PALLET | I11: 100000 | M11: 12.17 | N11: =VLOOKUP($B11,ma!$A:$C,3,0) -> 200000 | O11: =M11*N11 -> 2434000 | P11: =O11*10% -> 243400
A12: =A11+1 -> 7 | B12: TLX | C12: L4 HOÀ | D12: 46083 | E12: =VLOOKUP($C12,xe!$A:$B,2,0) -> 50E-324,01 | F12: =VLOOKUP($B12,ma!$A:$B,2,0) -> TUẤN LỘC Q7 XÁ | I12: 100000 | M12: 14.69 | N12: =VLOOKUP($B12,ma!$A:$C,3,0) -> 200000 | O12: =M12*N12 -> 2938000 | P12: =O12*10% -> 293800
A13: =A12+1 -> 8 | B13: NDNA | C13: L5 QUẠY | D13: 46083 | E13: =VLOOKUP($C13,xe!$A:$B,2,0) -> 50H-87055 | F13: =VLOOKUP($B13,ma!$A:$B,2,0) -> NDFC - NAIC BẾN LỨC | I13: 100000 | J13: bx | M13: 1 | N13: =VLOOKUP($B13,ma!$A:$C,3,0) -> 2400000 | O13: =M13*N13 -> 2400000 | P13: =O13*10% -> 240000
A14: =A13+1 -> 9 | B14: Q6P | C14: L5 QUẠY | D14: 46083 | E14: =VLOOKUP($C14,xe!$A:$B,2,0) -> 50H-87055 | F14: =VLOOKUP($B14,ma!$A:$B,2,0) -> PHẠM ANH QUẬN 6 PALLET | I14: 100000 | J14: bx | M14: 13.91 | N14: =VLOOKUP($B14,ma!$A:$C,3,0) -> 200000 | O14: =M14*N14 -> 2782000 | P14: =O14*10% -> 278200
A15: =A14+1 -> 10 | B15: ndna | C15: L1 THÀNH | D15: 46084 | E15: =VLOOKUP($C15,xe!$A:$B,2,0) -> 50E-648.73 | F15: =VLOOKUP($B15,ma!$A:$B,2,0) -> NDFC - NAIC BẾN LỨC | I15: 100000 | M15: 1 | N15: =VLOOKUP($B15,ma!$A:$C,3,0) -> 2400000 | O15: =M15*N15 -> 2400000 | P15: =O15*10% -> 240000
A16: 11 | B16: ndna | C16: L1 THÀNH | D16: 46084 | E16: =VLOOKUP($C16,xe!$A:$B,2,0) -> 50E-648.73 | F16: =VLOOKUP($B16,ma!$A:$B,2,0) -> NDFC - NAIC BẾN LỨC | I16: 100000 | M16: 1 | N16: =VLOOKUP($B16,ma!$A:$C,3,0) -> 2400000 | O16: =M16*N16 -> 2400000 | P16: =O16*10% -> 240000
A17: 12 | B17: ndna | C17: L1 THÀNH | D17: 46084 | E17: =VLOOKUP($C17,xe!$A:$B,2,0) -> 50E-648.73 | F17: =VLOOKUP($B17,ma!$A:$B,2,0) -> NDFC - NAIC BẾN LỨC | I17: 100000 | M17: 1 | N17: =VLOOKUP($B17,ma!$A:$C,3,0) -> 2400000 | O17: =M17*N17 -> 2400000 | P17: =O17*10% -> 240000
A18: 13 | B18: q8p | C18: L2 HOÀI | D18: 46084 | E18: =VLOOKUP($C18,xe!$A:$B,2,0) -> 50H-66347 | F18: =VLOOKUP($B18,ma!$A:$B,2,0) -> QUẬN 8 PALLET | I18: 100000 | J18: bx | M18: 14 | N18: =VLOOKUP($B18,ma!$A:$C,3,0) -> 200000 | O18: =M18*N18 -> 2800000 | P18: =O18*10% -> 280000
A19: 14 | B19: ghtgp | C19: L2 HOÀI | D19: 46084 | E19: =VLOOKUP($C19,xe!$A:$B,2,0) -> 50H-66347 | F19: =VLOOKUP($B19,ma!$A:$B,2,0) -> GIA HOÀNG TIỀN GIANG PALLET | I19: 100000 | J19: bx | M19: 14.58 | N19: =VLOOKUP($B19,ma!$A:$C,3,0) -> 230000 | O19: =M19*N19 -> 3353400 | P19: =O19*10% -> 335340
A20: 15 | B20: ndna | C20: L3 MẾN | D20: 46084 | E20: =VLOOKUP($C20,xe!$A:$B,2,0) -> 50E-654.34 | F20: =VLOOKUP($B20,ma!$A:$B,2,0) -> NDFC - NAIC BẾN LỨC | I20: 100000 | J20: bx | M20: 1 | N20: =VLOOKUP($B20,ma!$A:$C,3,0) -> 2400000 | O20: =M20*N20 -> 2400000 | P20: =O20*10% -> 240000
A21: 16 | B21: ndna | C21: L3 MẾN | D21: 46084 | E21: =VLOOKUP($C21,xe!$A:$B,2,0) -> 50E-654.34 | F21: =VLOOKUP($B21,ma!$A:$B,2,0) -> NDFC - NAIC BẾN LỨC | I21: 100000 | J21: bx | K21: 200000 | L21: cơm | M21: 1 | N21: =VLOOKUP($B21,ma!$A:$C,3,0) -> 2400000 | O21: =M21*N21 -> 2400000 | P21: =O21*10% -> 240000
A22: 17 | B22: tlp | C22: L4 HOÀ | D22: 46084 | E22: =VLOOKUP($C22,xe!$A:$B,2,0) -> 50E-324,01 | F22: =VLOOKUP($B22,ma!$A:$B,2,0) -> TUẤN LỘC Q7 PALLET | I22: 50000 | M22: 13.05 | N22: =VLOOKUP($B22,ma!$A:$C,3,0) -> 200000 | O22: =M22*N22 -> 2610000 | P22: =O22*10% -> 261000
A23: 18 | B23: tlp | C23: L4 HOÀ | D23: 46084 | E23: =VLOOKUP($C23,xe!$A:$B,2,0) -> 50E-324,01 | F23: =VLOOKUP($B23,ma!$A:$B,2,0) -> TUẤN LỘC Q7 PALLET | I23: 100000 | M23: 12 | N23: =VLOOKUP($B23,ma!$A:$C,3,0) -> 200000 | O23: =M23*N23 -> 2400000 | P23: =O23*10% -> 240000
A24: 19 | B24: ndna | C24: L5 QUẠY | D24: 46084 | E24: =VLOOKUP($C24,xe!$A:$B,2,0) -> 50H-87055 | F24: =VLOOKUP($B24,ma!$A:$B,2,0) -> NDFC - NAIC BẾN LỨC | I24: 100000 | J24: bx | M24: 1 | N24: =VLOOKUP($B24,ma!$A:$C,3,0) -> 2400000 | O24: =M24*N24 -> 2400000 | P24: =O24*10% -> 240000
A25: 20 | B25: ndna | C25: L5 QUẠY | D25: 46084 | E25: =VLOOKUP($C25,xe!$A:$B,2,0) -> 50H-87055 | F25: =VLOOKUP($B25,ma!$A:$B,2,0) -> NDFC - NAIC BẾN LỨC | I25: 100000 | J25: bx | K25: 200000 | L25: cơm | M25: 1 | N25: =VLOOKUP($B25,ma!$A:$C,3,0) -> 2400000 | O25: =M25*N25 -> 2400000 | P25: =O25*10% -> 240000
A26: 21 | B26: Q8X | C26: L1 THÀNH | D26: 46085 | E26: =VLOOKUP($C26,xe!$A:$B,2,0) -> 50E-648.73 | F26: =VLOOKUP($B26,ma!$A:$B,2,0) -> QUẬN 8 XÁ | I26: 250000 | M26: 14.2 | N26: =VLOOKUP($B26,ma!$A:$C,3,0) -> 200000 | O26: =M26*N26 -> 2840000 | P26: =O26*10% -> 284000
A27: 22 | B27: GHTGP | C27: L2 HOÀI | D27: 46085 | E27: =VLOOKUP($C27,xe!$A:$B,2,0) -> 50H-66347 | F27: =VLOOKUP($B27,ma!$A:$B,2,0) -> GIA HOÀNG TIỀN GIANG PALLET | I27: 100000 | J27: bx | M27: 13.75 | N27: =VLOOKUP($B27,ma!$A:$C,3,0) -> 230000 | O27: =M27*N27 -> 3162500 | P27: =O27*10% -> 316250
A28: 23 | B28: NAUN | C28: L2 HOÀI | D28: 46085 | E28: =VLOOKUP($C28,xe!$A:$B,2,0) -> 50H-66347 | F28: =VLOOKUP($B28,ma!$A:$B,2,0) -> NAIC -UNI | I28: 100000 | J28: bx | M28: 1 | N28: =VLOOKUP($B28,ma!$A:$C,3,0) -> 2400000 | O28: =M28*N28 -> 2400000 | P28: =O28*10% -> 240000
A29: 24 | B29: Q8X | C29: L3 MẾN | D29: 46085 | E29: =VLOOKUP($C29,xe!$A:$B,2,0) -> 50E-654.34 | F29: =VLOOKUP($B29,ma!$A:$B,2,0) -> QUẬN 8 XÁ | I29: 200000 | J29: bx | K29: 200000 | L29: châm ure | M29: 12 | N29: =VLOOKUP($B29,ma!$A:$C,3,0) -> 200000 | O29: =M29*N29 -> 2400000 | P29: =O29*10% -> 240000
A30: 25 | B30: NAUN | C30: L3 MẾN | D30: 46085 | E30: =VLOOKUP($C30,xe!$A:$B,2,0) -> 50E-654.34 | F30: =VLOOKUP($B30,ma!$A:$B,2,0) -> NAIC -UNI | I30: 100000 | J30: bx | M30: 1 | N30: =VLOOKUP($B30,ma!$A:$C,3,0) -> 2400000 | O30: =M30*N30 -> 2400000 | P30: =O30*10% -> 240000
A31: 26 | B31: TLP | C31: L4 HOÀ | D31: 46085 | E31: =VLOOKUP($C31,xe!$A:$B,2,0) -> 50E-324,01 | F31: =VLOOKUP($B31,ma!$A:$B,2,0) -> TUẤN LỘC Q7 PALLET | I31: 50000 | M31: 12.46 | N31: =VLOOKUP($B31,ma!$A:$C,3,0) -> 200000 | O31: =M31*N31 -> 2492000 | P31: =O31*10% -> 249200
A32: 27 | B32: TLP | C32: L4 HOÀ | D32: 46085 | E32: =VLOOKUP($C32,xe!$A:$B,2,0) -> 50E-324,01 | F32: =VLOOKUP($B32,ma!$A:$B,2,0) -> TUẤN LỘC Q7 PALLET | I32: 100000 | M32: 12 | N32: =VLOOKUP($B32,ma!$A:$C,3,0) -> 200000 | O32: =M32*N32 -> 2400000 | P32: =O32*10% -> 240000
A33: 28 | B33: TTHOA | C33: L4 HOÀ | D33: 46085 | E33: =VLOOKUP($C33,xe!$A:$B,2,0) -> 50E-324,01 | F33: =VLOOKUP($B33,ma!$A:$B,2,0) -> THẮNG THOA PHƯƠNG LÂM | I33: 100000 | M33: 12 | N33: =VLOOKUP($B33,ma!$A:$C,3,0) -> 300000 | O33: =M33*N33 -> 3600000 | P33: =O33*10% -> 360000
A34: 29 | B34: TLP | C34: L5 QUẠY | D34: 46085 | E34: =VLOOKUP($C34,xe!$A:$B,2,0) -> 50H-87055 | F34: =VLOOKUP($B34,ma!$A:$B,2,0) -> TUẤN LỘC Q7 PALLET | I34: 100000 | J34: bx | K34: 50000 | L34: trả pl | M34: 12 | N34: =VLOOKUP($B34,ma!$A:$C,3,0) -> 200000 | O34: =M34*N34 -> 2400000 | P34: =O34*10% -> 240000
A35: 30 | B35: NAUN | C35: L5 QUẠY | D35: 46085 | E35: =VLOOKUP($C35,xe!$A:$B,2,0) -> 50H-87055 | F35: =VLOOKUP($B35,ma!$A:$B,2,0) -> NAIC -UNI | I35: 100000 | J35: bx | M35: 1 | N35: =VLOOKUP($B35,ma!$A:$C,3,0) -> 2400000 | O35: =M35*N35 -> 2400000 | P35: =O35*10% -> 240000
A36: 31 | B36: naun | C36: L1 THÀNH | D36: 46086 | E36: =VLOOKUP($C36,xe!$A:$B,2,0) -> 50E-648.73 | F36: =VLOOKUP($B36,ma!$A:$B,2,0) -> NAIC -UNI | I36: 100000 | M36: 1 | N36: =VLOOKUP($B36,ma!$A:$C,3,0) -> 2400000 | O36: =M36*N36 -> 2400000 | P36: =O36*10% -> 240000
A37: 32 | B37: naun | C37: L1 THÀNH | D37: 46086 | E37: =VLOOKUP($C37,xe!$A:$B,2,0) -> 50E-648.73 | F37: =VLOOKUP($B37,ma!$A:$B,2,0) -> NAIC -UNI | I37: 100000 | M37: 1 | N37: =VLOOKUP($B37,ma!$A:$C,3,0) -> 2400000 | O37: =M37*N37 -> 2400000 | P37: =O37*10% -> 240000
A38: 33 | B38: tlp | C38: L2 HOÀI | D38: 46086 | E38: =VLOOKUP($C38,xe!$A:$B,2,0) -> 50H-66347 | F38: =VLOOKUP($B38,ma!$A:$B,2,0) -> TUẤN LỘC Q7 PALLET | I38: 50000 | J38: bx | K38: 100000 | L38: keo dán bạc | M38: 12.46 | N38: =VLOOKUP($B38,ma!$A:$C,3,0) -> 200000 | O38: =M38*N38 -> 2492000 | P38: =O38*10% -> 249200
A39: 34 | B39: tlp | C39: L2 HOÀI | D39: 46086 | E39: =VLOOKUP($C39,xe!$A:$B,2,0) -> 50H-66347 | F39: =VLOOKUP($B39,ma!$A:$B,2,0) -> TUẤN LỘC Q7 PALLET | I39: 100000 | J39: bx | M39: 14.1 | N39: =VLOOKUP($B39,ma!$A:$C,3,0) -> 200000 | O39: =M39*N39 -> 2820000 | P39: =O39*10% -> 282000
A40: 35 | B40: lkx | C40: L3 MẾN | D40: 46086 | E40: =VLOOKUP($C40,xe!$A:$B,2,0) -> 50E-654.34 | F40: =VLOOKUP($B40,ma!$A:$B,2,0) -> LONG KHÁNH XÁ | I40: 200000 | J40: bx | M40: 15.35 | N40: =VLOOKUP($B40,ma!$A:$C,3,0) -> 244000 | O40: =M40*N40 -> 3745400 | P40: =O40*10% -> 374540
...

Sheet TRUNG CHUYỂN
D1: KÊ CHI TIẾT XE LỚN | P1: PHƯƠNG | Q1: 50H-75206
D2: 46054 | P2: ÂN | Q2: 50H-55294
D3: Tên : | G3: SỐ XE : | P3: HOÀNG | Q3: 50H-55129
F4: #N/A | K4: 2 | L4: 2 | N4: #N/A | P4: HẢI | Q4: 50H-69717
A5: STT | B5: Mã | C5: Tên TX | D5: Ngày | E5: Số Xe | F5: Nơi giao | G5: Đổ Dầu | H5: SỐ KM | I5: C.phí tài xế | J5: ghi chú | K5: Cầu đường | L5: ghi chú | M5: TÀI | N5: Đơn giá | O5: Thành tiền | P5: LƯƠNG LX
A6: 1 | B6: calo | C6: l10 hải | D6: 46082 | E6: =VLOOKUP($C6,xe!$A:$B,2,0) -> 50H-69717 | F6: =VLOOKUP($B6,ma!$A:$B,2,0) -> Chuyển hàng Calofic | I6: 200000 | J6: CHỦ NHẬT | M6: 6 | N6: =VLOOKUP($B6,ma!$A:$C,3,0) -> 180000 | O6: =M6*N6 -> 1080000 | P6: =M6*50000 -> 300000
A7: 2 | B7: calo | C7: l7 phương | D7: 46082 | E7: =VLOOKUP($C7,xe!$A:$B,2,0) -> 50H-75206 | F7: =VLOOKUP($B7,ma!$A:$B,2,0) -> Chuyển hàng Calofic | J7: CHỦ NHẬT | M7: 7 | N7: =VLOOKUP($B7,ma!$A:$C,3,0) -> 180000 | O7: =M7*N7 -> 1260000 | P7: =M7*50000 -> 350000
A8: 3 | B8: ndfc | C8: l8 ân | D8: 46083 | E8: =VLOOKUP($C8,xe!$A:$B,2,0) -> 50H-55294 | F8: =VLOOKUP($B8,ma!$A:$B,2,0) -> Chuyển Hàng ndfc | M8: 2 | N8: =VLOOKUP($B8,ma!$A:$C,3,0) -> 410000 | O8: =M8*N8 -> 820000 | P8: 200000
A9: 4 | B9: calo | C9: l10 hải | D9: 46083 | E9: =VLOOKUP($C9,xe!$A:$B,2,0) -> 50H-69717 | F9: =VLOOKUP($B9,ma!$A:$B,2,0) -> Chuyển hàng Calofic | M9: 11 | N9: =VLOOKUP($B9,ma!$A:$C,3,0) -> 180000 | O9: =M9*N9 -> 1980000 | P9: =M9*50000 -> 550000
A10: 5 | B10: m6 | C10: l7 phương | D10: 46083 | E10: =VLOOKUP($C10,xe!$A:$B,2,0) -> 50H-75206 | F10: =VLOOKUP($B10,ma!$A:$B,2,0) -> MCC 6 CHUYẾN | I10: 60000 | J10: clf | K10: 400000 | L10: Vá vỏ bơm mỡ | M10: 9 | N10: =VLOOKUP($B10,ma!$A:$C,3,0) -> 300000 | O10: =M10*N10 -> 2700000 | P10: 900000
A11: 6 | B11: NDFC | C11: l8 ân | D11: 46084 | E11: =VLOOKUP($C11,xe!$A:$B,2,0) -> 50H-55294 | F11: =VLOOKUP($B11,ma!$A:$B,2,0) -> Chuyển Hàng ndfc | M11: 4 | N11: =VLOOKUP($B11,ma!$A:$C,3,0) -> 410000 | O11: =M11*N11 -> 1640000 | P11: 400000
A12: 7 | B12: m6 | C12: l7 phương | D12: 46084 | E12: =VLOOKUP($C12,xe!$A:$B,2,0) -> 50H-75206 | F12: =VLOOKUP($B12,ma!$A:$B,2,0) -> MCC 6 CHUYẾN | I12: 20000 | J12: clf | K12: 2400000 | L12: 6 CỤC CAO SU NHÍP | M12: 6 | N12: =VLOOKUP($B12,ma!$A:$C,3,0) -> 300000 | O12: =M12*N12 -> 1800000 | P12: 600000
A13: 8 | B13: calo | C13: l10 hải | D13: 46084 | E13: =VLOOKUP($C13,xe!$A:$B,2,0) -> 50H-69717 | F13: =VLOOKUP($B13,ma!$A:$B,2,0) -> Chuyển hàng Calofic | M13: 7 | N13: =VLOOKUP($B13,ma!$A:$C,3,0) -> 180000 | O13: =M13*N13 -> 1260000 | P13: =M13*50000 -> 350000
A14: 9 | B14: ndfc | C14: l8 ân | D14: 46085 | E14: =VLOOKUP($C14,xe!$A:$B,2,0) -> 50H-55294 | F14: =VLOOKUP($B14,ma!$A:$B,2,0) -> Chuyển Hàng ndfc | M14: 4 | N14: =VLOOKUP($B14,ma!$A:$C,3,0) -> 410000 | O14: =M14*N14 -> 1640000 | P14: 400000
A15: 10 | B15: mcc | C15: l7 phương | D15: 46085 | E15: =VLOOKUP($C15,xe!$A:$B,2,0) -> 50H-75206 | F15: =VLOOKUP($B15,ma!$A:$B,2,0) -> Chuyển hàng MCC | I15: 40000 | J15: clf | K15: 4600000 | L15: xét xe | M15: 5 | N15: =VLOOKUP($B15,ma!$A:$C,3,0) -> 414000 | O15: =M15*N15 -> 2070000 | P15: 500000
A16: 11 | B16: calo | C16: l10 hải | D16: 46085 | E16: =VLOOKUP($C16,xe!$A:$B,2,0) -> 50H-69717 | F16: =VLOOKUP($B16,ma!$A:$B,2,0) -> Chuyển hàng Calofic | M16: 10 | N16: =VLOOKUP($B16,ma!$A:$C,3,0) -> 180000 | O16: =M16*N16 -> 1800000 | P16: =M16*50000 -> 500000
A17: 12 | B17: m6 | C17: l7 phương | D17: 46086 | E17: =VLOOKUP($C17,xe!$A:$B,2,0) -> 50H-75206 | F17: =VLOOKUP($B17,ma!$A:$B,2,0) -> MCC 6 CHUYẾN | I17: 40000 | J17: clf | K17: 2000000 | L17: cò xét xe | M17: 6 | N17: =VLOOKUP($B17,ma!$A:$C,3,0) -> 300000 | O17: =M17*N17 -> 1800000 | P17: 600000
A18: 13 | B18: ndfc | C18: l8 ân | D18: 46086 | E18: =VLOOKUP($C18,xe!$A:$B,2,0) -> 50H-55294 | F18: =VLOOKUP($B18,ma!$A:$B,2,0) -> Chuyển Hàng ndfc | M18: 4 | N18: =VLOOKUP($B18,ma!$A:$C,3,0) -> 410000 | O18: =M18*N18 -> 1640000 | P18: 400000
A19: 14 | B19: calo | C19: l10 hải | D19: 46086 | E19: =VLOOKUP($C19,xe!$A:$B,2,0) -> 50H-69717 | F19: =VLOOKUP($B19,ma!$A:$B,2,0) -> Chuyển hàng Calofic | M19: 9 | N19: =VLOOKUP($B19,ma!$A:$C,3,0) -> 180000 | O19: =M19*N19 -> 1620000 | P19: =M19*50000 -> 450000
A20: 15 | B20: NDFC | C20: l8 ân | D20: 46087 | E20: =VLOOKUP($C20,xe!$A:$B,2,0) -> 50H-55294 | F20: =VLOOKUP($B20,ma!$A:$B,2,0) -> Chuyển Hàng ndfc | M20: 3 | N20: =VLOOKUP($B20,ma!$A:$C,3,0) -> 410000 | O20: =M20*N20 -> 1230000 | P20: 300000
A21: 16 | B21: CALO | C21: l10 hải | D21: 46087 | E21: =VLOOKUP($C21,xe!$A:$B,2,0) -> 50H-69717 | F21: =VLOOKUP($B21,ma!$A:$B,2,0) -> Chuyển hàng Calofic | M21: 10 | N21: =VLOOKUP($B21,ma!$A:$C,3,0) -> 180000 | O21: =M21*N21 -> 1800000 | P21: =M21*50000 -> 500000
A22: 17 | B22: mcc | C22: l7 phương | D22: 46087 | E22: =VLOOKUP($C22,xe!$A:$B,2,0) -> 50H-75206 | F22: =VLOOKUP($B22,ma!$A:$B,2,0) -> Chuyển hàng MCC | K22: 5000000 | L22: thay bộ thắng tay | M22: 3 | N22: =VLOOKUP($B22,ma!$A:$C,3,0) -> 414000 | O22: =M22*N22 -> 1242000 | P22: 300000
A23: 18 | B23: cluni | C23: l8 ân | D23: 46087 | E23: =VLOOKUP($C23,xe!$A:$B,2,0) -> 50H-55294 | F23: =VLOOKUP($B23,ma!$A:$B,2,0) -> CALOFIC - UNI ( xe lớn ) | M23: 2 | N23: =VLOOKUP($B23,ma!$A:$C,3,0) -> 400000 | O23: =M23*N23 -> 800000 | P23: 200000
A24: 19 | B24: tlp | C24: l7 phương | D24: 46087 | E24: =VLOOKUP($C24,xe!$A:$B,2,0) -> 50H-75206 | F24: =VLOOKUP($B24,ma!$A:$B,2,0) -> TUẤN LỘC Q7 PALLET | I24: 100000 | J24: bx | K24: 1970000 | L24: MUA BẢO HIỂM XE | M24: 12 | N24: =VLOOKUP($B24,ma!$A:$C,3,0) -> 200000 | O24: =M24*N24 -> 2400000 | P24: 400000
A25: 20 | B25: calo | C25: l9 hoàng | D25: 46088 | E25: =VLOOKUP($C25,xe!$A:$B,2,0) -> 50H-55129 | F25: =VLOOKUP($B25,ma!$A:$B,2,0) -> Chuyển hàng Calofic | M25: 13 | N25: =VLOOKUP($B25,ma!$A:$C,3,0) -> 180000 | O25: =M25*N25 -> 2340000 | P25: =M25*50000 -> 650000
A26: 21 | B26: calo | C26: l10 hải | D26: 46088 | E26: =VLOOKUP($C26,xe!$A:$B,2,0) -> 50H-69717 | F26: =VLOOKUP($B26,ma!$A:$B,2,0) -> Chuyển hàng Calofic | M26: 12 | N26: =VLOOKUP($B26,ma!$A:$C,3,0) -> 180000 | O26: =M26*N26 -> 2160000 | P26: =M26*50000 -> 600000
A27: 22 | B27: mcc | C27: l7 phương | D27: 46088 | E27: =VLOOKUP($C27,xe!$A:$B,2,0) -> 50H-75206 | F27: =VLOOKUP($B27,ma!$A:$B,2,0) -> Chuyển hàng MCC | K27: 1000000 | L27: vệ sinh máy lạnh bơm ga | M27: 4 | N27: =VLOOKUP($B27,ma!$A:$C,3,0) -> 414000 | O27: =M27*N27 -> 1656000 | P27: 400000
A28: 22 | B28: cluni | C28: l8 ân | D28: 46088 | E28: =VLOOKUP($C28,xe!$A:$B,2,0) -> 50H-55294 | F28: =VLOOKUP($B28,ma!$A:$B,2,0) -> CALOFIC - UNI ( xe lớn ) | M28: 2 | N28: =VLOOKUP($B28,ma!$A:$C,3,0) -> 400000 | O28: =M28*N28 -> 800000 | P28: 200000
A29: 23 | B29: ndfc | C29: l8 ân | D29: 46088 | E29: =VLOOKUP($C29,xe!$A:$B,2,0) -> 50H-55294 | F29: =VLOOKUP($B29,ma!$A:$B,2,0) -> Chuyển Hàng ndfc | M29: 2 | N29: =VLOOKUP($B29,ma!$A:$C,3,0) -> 410000 | O29: =M29*N29 -> 820000 | P29: 200000
A30: 24 | B30: calo | C30: l9 hoàng | D30: 46089 | E30: =VLOOKUP($C30,xe!$A:$B,2,0) -> 50H-55129 | F30: =VLOOKUP($B30,ma!$A:$B,2,0) -> Chuyển hàng Calofic | I30: 200000 | J30: CHỦ NHẬT | M30: 5 | N30: =VLOOKUP($B30,ma!$A:$C,3,0) -> 180000 | O30: =M30*N30 -> 900000 | P30: =M30*50000 -> 250000
A31: 25 | B31: calo | C31: l10 hải | D31: 46089 | E31: =VLOOKUP($C31,xe!$A:$B,2,0) -> 50H-69717 | F31: =VLOOKUP($B31,ma!$A:$B,2,0) -> Chuyển hàng Calofic | I31: 200000 | J31: CHỦ NHẬT | M31: 7 | N31: =VLOOKUP($B31,ma!$A:$C,3,0) -> 180000 | O31: =M31*N31 -> 1260000 | P31: =M31*50000 -> 350000
A32: 26 | B32: m6 | C32: l7 phương | D32: 46090 | E32: =VLOOKUP($C32,xe!$A:$B,2,0) -> 50H-75206 | F32: =VLOOKUP($B32,ma!$A:$B,2,0) -> MCC 6 CHUYẾN | I32: 40000 | J32: clf | K32: 850000 | L32: thay cây gạt mưa | M32: 6 | N32: =VLOOKUP($B32,ma!$A:$C,3,0) -> 300000 | O32: =M32*N32 -> 1800000 | P32: 600000
A33: 27 | B33: ndfc | C33: l8 ân | D33: 46090 | E33: =VLOOKUP($C33,xe!$A:$B,2,0) -> 50H-55294 | F33: =VLOOKUP($B33,ma!$A:$B,2,0) -> Chuyển Hàng ndfc | M33: 5 | N33: =VLOOKUP($B33,ma!$A:$C,3,0) -> 410000 | O33: =M33*N33 -> 2050000 | P33: 500000
A34: 28 | B34: calo | C34: l9 hoàng | D34: 46090 | E34: =VLOOKUP($C34,xe!$A:$B,2,0) -> 50H-55129 | F34: =VLOOKUP($B34,ma!$A:$B,2,0) -> Chuyển hàng Calofic | M34: 9 | N34: =VLOOKUP($B34,ma!$A:$C,3,0) -> 180000 | O34: =M34*N34 -> 1620000 | P34: =M34*50000 -> 450000
A35: 29 | B35: calo | C35: l10 hải | D35: 46090 | E35: =VLOOKUP($C35,xe!$A:$B,2,0) -> 50H-69717 | F35: =VLOOKUP($B35,ma!$A:$B,2,0) -> Chuyển hàng Calofic | M35: 8 | N35: =VLOOKUP($B35,ma!$A:$C,3,0) -> 180000 | O35: =M35*N35 -> 1440000 | P35: =M35*50000 -> 400000
A36: 30 | B36: mcc | C36: l7 phương | D36: 46091 | E36: =VLOOKUP($C36,xe!$A:$B,2,0) -> 50H-75206 | F36: =VLOOKUP($B36,ma!$A:$B,2,0) -> Chuyển hàng MCC | I36: 20000 | J36: clf | K36: 3200000 | L36: Bọc ghế + giường | M36: 5 | N36: =VLOOKUP($B36,ma!$A:$C,3,0) -> 414000 | O36: =M36*N36 -> 2070000 | P36: 500000
A37: 32 | B37: ndfc | C37: l8 ân | D37: 46091 | E37: =VLOOKUP($C37,xe!$A:$B,2,0) -> 50H-55294 | F37: =VLOOKUP($B37,ma!$A:$B,2,0) -> Chuyển Hàng ndfc | M37: 4 | N37: =VLOOKUP($B37,ma!$A:$C,3,0) -> 410000 | O37: =M37*N37 -> 1640000 | P37: 400000
A38: 33 | B38: calo | C38: l9 hoàng | D38: 46091 | E38: =VLOOKUP($C38,xe!$A:$B,2,0) -> 50H-55129 | F38: =VLOOKUP($B38,ma!$A:$B,2,0) -> Chuyển hàng Calofic | M38: 10 | N38: =VLOOKUP($B38,ma!$A:$C,3,0) -> 180000 | O38: =M38*N38 -> 1800000 | P38: =M38*50000 -> 500000
A39: 34 | B39: calo | C39: l10 hải | D39: 46091 | E39: =VLOOKUP($C39,xe!$A:$B,2,0) -> 50H-69717 | F39: =VLOOKUP($B39,ma!$A:$B,2,0) -> Chuyển hàng Calofic | M39: 10 | N39: =VLOOKUP($B39,ma!$A:$C,3,0) -> 180000 | O39: =M39*N39 -> 1800000 | P39: =M39*50000 -> 500000
A40: 35 | B40: mcc | C40: l7 phương | D40: 46092 | E40: =VLOOKUP($C40,xe!$A:$B,2,0) -> 50H-75206 | F40: =VLOOKUP($B40,ma!$A:$B,2,0) -> Chuyển hàng MCC | I40: 20000 | J40: clf | K40: 18200000 | L40: làm thùng xe | M40: 2 | N40: =VLOOKUP($B40,ma!$A:$C,3,0) -> 414000 | O40: =M40*N40 -> 828000 | P40: 200000
...

Sheet 50H-88294
C1: KÊ CHI TIẾT 50H-88294
C2: 46112
C3: Tên : | E3: SỐ XE : | I3: 50H-88294
D4: #N/A | L4: #N/A
A5: STT | B5: Mã | C5: Ngày | D5: Nơi giao | E5: Đổ Dầu | F5: SỐ KM | G5: CẦU ĐƯỜNG | H5: Ghi chú | I5: C.phí c.xe | J5: ghi chú | K5: TÀI | L5: Đơn giá | M5: Thành tiền | O5: MUA XE 51C-89727
A6: 1 | D6: =VLOOKUP($B6,ma!$A:$B,2,0) -> #N/A | K6: 1 | L6: =VLOOKUP($B6,ma!$A:$C,3,0) -> #N/A | M6: =VLOOKUP($B6,ma!$A:$C,3,0) -> #N/A | O6: 45372 | P6: 305000000 | Q6: GIÁ XE
A7: 2 | D7: =VLOOKUP($B7,ma!$A:$B,2,0) -> #N/A | K7: 1 | L7: =VLOOKUP($B7,ma!$A:$C,3,0) -> #N/A | M7: =VLOOKUP($B7,ma!$A:$C,3,0) -> #N/A | O7: 45372 | P7: 3500000 | Q7: CÀ PHÊ
A8: 3 | D8: =VLOOKUP($B8,ma!$A:$B,2,0) -> #N/A | K8: 1 | L8: =VLOOKUP($B8,ma!$A:$C,3,0) -> #N/A | M8: =VLOOKUP($B8,ma!$A:$C,3,0) -> #N/A | P8: 640000 | Q8: BẢO HIỂM XE
A9: 4 | D9: =VLOOKUP($B9,ma!$A:$B,2,0) -> #N/A | K9: 1 | L9: =VLOOKUP($B9,ma!$A:$C,3,0) -> #N/A | M9: =VLOOKUP($B9,ma!$A:$C,3,0) -> #N/A | P9: 2300000 | Q9: ĐỊNH VỊ XE
A10: 5 | D10: =VLOOKUP($B10,ma!$A:$B,2,0) -> #N/A | K10: 1 | L10: =VLOOKUP($B10,ma!$A:$C,3,0) -> #N/A | M10: =VLOOKUP($B10,ma!$A:$C,3,0) -> #N/A | O10: 45373 | P10: 8000000 | Q10: DẦU MÁY
A11: 6 | D11: =VLOOKUP($B11,ma!$A:$B,2,0) -> #N/A | K11: 1 | L11: =VLOOKUP($B11,ma!$A:$C,3,0) -> #N/A | M11: =VLOOKUP($B11,ma!$A:$C,3,0) -> #N/A | O11: 45373 | P11: 3810000 | Q11: bảo dưỡng xe
A12: 7 | D12: =VLOOKUP($B12,ma!$A:$B,2,0) -> #N/A | K12: 1 | L12: =VLOOKUP($B12,ma!$A:$C,3,0) -> #N/A | M12: =VLOOKUP($B12,ma!$A:$C,3,0) -> #N/A | O12: 45373 | P12: 1100000 | Q12: MUA ĐÈN THÙNG
A13: 8 | D13: =VLOOKUP($B13,ma!$A:$B,2,0) -> #N/A | K13: 1 | L13: =VLOOKUP($B13,ma!$A:$C,3,0) -> #N/A | M13: =VLOOKUP($B13,ma!$A:$C,3,0) -> #N/A | O13: 45550 | P13: 9000000 | Q13: thay 4 vỏ sau
A14: 9 | D14: =VLOOKUP($B14,ma!$A:$B,2,0) -> #N/A | K14: 1 | L14: =VLOOKUP($B14,ma!$A:$C,3,0) -> #N/A | M14: =VLOOKUP($B14,ma!$A:$C,3,0) -> #N/A
A15: 10 | D15: =VLOOKUP($B15,ma!$A:$B,2,0) -> #N/A | K15: 1 | L15: =VLOOKUP($B15,ma!$A:$C,3,0) -> #N/A | M15: =VLOOKUP($B15,ma!$A:$C,3,0) -> #N/A | P15: =SUM(P6:P14) -> 333350000
A16: 11 | D16: =VLOOKUP($B16,ma!$A:$B,2,0) -> #N/A | K16: 1 | L16: =VLOOKUP($B16,ma!$A:$C,3,0) -> #N/A | M16: =VLOOKUP($B16,ma!$A:$C,3,0) -> #N/A
A17: 12 | D17: =VLOOKUP($B17,ma!$A:$B,2,0) -> #N/A | K17: 1 | L17: =VLOOKUP($B17,ma!$A:$C,3,0) -> #N/A | M17: =VLOOKUP($B17,ma!$A:$C,3,0) -> #N/A | O17: MUA XE | P17: 317,150,000
A18: 13 | D18: =VLOOKUP($B18,ma!$A:$B,2,0) -> #N/A | K18: 1 | L18: =VLOOKUP($B18,ma!$A:$C,3,0) -> #N/A | M18: =VLOOKUP($B18,ma!$A:$C,3,0) -> #N/A | O18: D.THU 3/2024 | P18: 2,830,000
A19: 14 | D19: =VLOOKUP($B19,ma!$A:$B,2,0) -> #N/A | K19: 1 | L19: =VLOOKUP($B19,ma!$A:$C,3,0) -> #N/A | M19: =VLOOKUP($B19,ma!$A:$C,3,0) -> #N/A | P19: 314,320,000
A20: 15 | D20: =VLOOKUP($B20,ma!$A:$B,2,0) -> #N/A | K20: 1 | L20: =VLOOKUP($B20,ma!$A:$C,3,0) -> #N/A | M20: =VLOOKUP($B20,ma!$A:$C,3,0) -> #N/A | O20: CHIA ĐÔI | P20: 157,160,000
A21: 16 | D21: =VLOOKUP($B21,ma!$A:$B,2,0) -> #N/A | K21: 1 | L21: =VLOOKUP($B21,ma!$A:$C,3,0) -> #N/A | M21: =VLOOKUP($B21,ma!$A:$C,3,0) -> #N/A
A22: 17 | D22: =VLOOKUP($B22,ma!$A:$B,2,0) -> #N/A | K22: 1 | L22: =VLOOKUP($B22,ma!$A:$C,3,0) -> #N/A | M22: =VLOOKUP($B22,ma!$A:$C,3,0) -> #N/A
A23: 18 | D23: =VLOOKUP($B23,ma!$A:$B,2,0) -> #N/A | K23: 1 | L23: =VLOOKUP($B23,ma!$A:$C,3,0) -> #N/A | M23: =VLOOKUP($B23,ma!$A:$C,3,0) -> #N/A
A24: 19 | D24: =VLOOKUP($B24,ma!$A:$B,2,0) -> #N/A | K24: 1 | L24: =VLOOKUP($B24,ma!$A:$C,3,0) -> #N/A | M24: =VLOOKUP($B24,ma!$A:$C,3,0) -> #N/A
A25: 20 | D25: =VLOOKUP($B25,ma!$A:$B,2,0) -> #N/A | K25: 1 | L25: =VLOOKUP($B25,ma!$A:$C,3,0) -> #N/A | M25: =VLOOKUP($B25,ma!$A:$C,3,0) -> #N/A
A26: 21 | D26: =VLOOKUP($B26,ma!$A:$B,2,0) -> #N/A | K26: 1 | L26: =VLOOKUP($B26,ma!$A:$C,3,0) -> #N/A | M26: =VLOOKUP($B26,ma!$A:$C,3,0) -> #N/A
A27: 22 | D27: =VLOOKUP($B27,ma!$A:$B,2,0) -> #N/A | K27: 1 | L27: =VLOOKUP($B27,ma!$A:$C,3,0) -> #N/A | M27: =VLOOKUP($B27,ma!$A:$C,3,0) -> #N/A
A28: 23 | D28: =VLOOKUP($B28,ma!$A:$B,2,0) -> #N/A | K28: 1 | L28: =VLOOKUP($B28,ma!$A:$C,3,0) -> #N/A | M28: =VLOOKUP($B28,ma!$A:$C,3,0) -> #N/A
A29: 24 | D29: =VLOOKUP($B29,ma!$A:$B,2,0) -> #N/A | K29: 1 | L29: =VLOOKUP($B29,ma!$A:$C,3,0) -> #N/A | M29: =VLOOKUP($B29,ma!$A:$C,3,0) -> #N/A
A30: 25 | D30: =VLOOKUP($B30,ma!$A:$B,2,0) -> #N/A | K30: 1 | L30: =VLOOKUP($B30,ma!$A:$C,3,0) -> #N/A | M30: =VLOOKUP($B30,ma!$A:$C,3,0) -> #N/A
A31: 26 | D31: =VLOOKUP($B31,ma!$A:$B,2,0) -> #N/A | K31: 1 | L31: =VLOOKUP($B31,ma!$A:$C,3,0) -> #N/A | M31: =VLOOKUP($B31,ma!$A:$C,3,0) -> #N/A
A32: 27 | D32: =VLOOKUP($B32,ma!$A:$B,2,0) -> #N/A | K32: 1 | L32: =VLOOKUP($B32,ma!$A:$C,3,0) -> #N/A | M32: =VLOOKUP($B32,ma!$A:$C,3,0) -> #N/A
... A48: 43 | D48: =VLOOKUP($B48,ma!$A:$B,2,0) -> #N/A | K48: 1 | L48: =VLOOKUP($B48,ma!$A:$C,3,0) -> #N/A | M48: =VLOOKUP($B48,ma!$A:$C,3,0) -> #N/A
C49: Tổng cộng : | F49: 176.89 | G49: =SUM(G6:G48) -> 0 | I49: =SUM(I6:I48) -> 0 | K49: 43 | M49: =SUM(M6:M48) -> #N/A
C50: Doanh Thu | D50: 33,550,000 | P50: doanh thu 03/2024
C51: Chi Phí | D51: =G49+I49 -> 0 | G51: doanh thu 01/2025 | P51: doanh thu 04/2024 | Q51: 10750000
C52: Lương | D52: 7,800,000 | G52: 45658 | H52: 4000000 | P52: doanh thu 05/2024 | Q52: 9510000
G53: 45689 | H53: 7760000 | P53: doanh thu 06/2024 | Q53: 7010000
C54: BHXH | D54: 1,100,000 | G54: 45717 | H54: 14900000 | P54: doanh thu 07/2024 | Q54: 15600000
C55: Còn Lại | D55: 13,740,000 | G55: 45748 | H55: 11400000 | P55: doanh thu 08/2024 | Q55: 14160000
...

Sheet 50H-74619
C1: BẢNG KÊ 50H-74619
C2: 45930
C3: Tên : | D3: THẠCH | E3: SỐ XE : | I3: 50H-74619
D4: #N/A | L4: #N/A
A5: STT | B5: Mã | C5: Ngày | D5: Nơi giao | E5: Đổ Dầu | F5: SỐ KM | G5: CẦU ĐƯỜNG | H5: Ghi chú | I5: C.phí c.xe | J5: ghi chú | K5: TÀI | L5: Đơn giá | M5: Thành tiền | O5: MUA XE 50H-74619
A6: 1 | D6: =VLOOKUP($B6,ma!$A:$B,2,0) -> #N/A | I6: 900000 | J6: BÃI XE | K6: 1 | L6: =VLOOKUP($B6,ma!$A:$C,3,0) -> #N/A | M6: =VLOOKUP($B6,ma!$A:$C,3,0) -> #N/A | O6: 45667 | P6: 426000000 | Q6: MUA XE
A7: 2 | D7: =VLOOKUP($B7,ma!$A:$B,2,0) -> #N/A | K7: 1 | L7: =VLOOKUP($B7,ma!$A:$C,3,0) -> #N/A | M7: =VLOOKUP($B7,ma!$A:$C,3,0) -> #N/A | O7: 45667 | P7: 1000000 | Q7: XE KÉO VỀ BÃI
A8: 3 | D8: =VLOOKUP($B8,ma!$A:$B,2,0) -> #N/A | K8: 1 | L8: =VLOOKUP($B8,ma!$A:$C,3,0) -> #N/A | M8: =VLOOKUP($B8,ma!$A:$C,3,0) -> #N/A | O8: 45669 | P8: 2460000 | Q8: ĐỊNH VỊ
A9: 4 | D9: =VLOOKUP($B9,ma!$A:$B,2,0) -> #N/A | K9: 1 | L9: =VLOOKUP($B9,ma!$A:$C,3,0) -> #N/A | M9: =VLOOKUP($B9,ma!$A:$C,3,0) -> #N/A | O9: 45669 | P9: 5450000 | Q9: thuế trước bạ
A10: 5 | D10: =VLOOKUP($B10,ma!$A:$B,2,0) -> #N/A | K10: 1 | L10: =VLOOKUP($B10,ma!$A:$C,3,0) -> #N/A | M10: =VLOOKUP($B10,ma!$A:$C,3,0) -> #N/A | O10: 45669 | P10: 3500000 | Q10: cò giấy tờ
A11: 6 | D11: =VLOOKUP($B11,ma!$A:$B,2,0) -> #N/A | K11: 1 | L11: =VLOOKUP($B11,ma!$A:$C,3,0) -> #N/A | M11: =VLOOKUP($B11,ma!$A:$C,3,0) -> #N/A | O11: 45671 | P11: 1280000 | Q11: xét xe
A12: 7 | D12: =VLOOKUP($B12,ma!$A:$B,2,0) -> #N/A | K12: 1 | L12: =VLOOKUP($B12,ma!$A:$C,3,0) -> #N/A | M12: =VLOOKUP($B12,ma!$A:$C,3,0) -> #N/A | O12: 45672 | P12: 640000 | Q12: bảo hiểm xe
A13: 8 | D13: =VLOOKUP($B13,ma!$A:$B,2,0) -> #N/A | K13: 1 | L13: =VLOOKUP($B13,ma!$A:$C,3,0) -> #N/A | M13: =VLOOKUP($B13,ma!$A:$C,3,0) -> #N/A | O13: 45673 | P13: 500000 | Q13: Phù hiệu xe
A14: 9 | D14: =VLOOKUP($B14,ma!$A:$B,2,0) -> #N/A | K14: 1 | L14: =VLOOKUP($B14,ma!$A:$C,3,0) -> #N/A | M14: =VLOOKUP($B14,ma!$A:$C,3,0) -> #N/A | O14: 45675 | P14: 3450000 | Q14: Thay bình ắc quy
A15: 10 | D15: =VLOOKUP($B15,ma!$A:$B,2,0) -> #N/A | K15: 1 | L15: =VLOOKUP($B15,ma!$A:$C,3,0) -> #N/A | M15: =VLOOKUP($B15,ma!$A:$C,3,0) -> #N/A | O15: 45676 | P15: 830000 | Q15: mua đồ
A16: 11 | D16: =VLOOKUP($B16,ma!$A:$B,2,0) -> #N/A | K16: 1 | L16: =VLOOKUP($B16,ma!$A:$C,3,0) -> #N/A | M16: =VLOOKUP($B16,ma!$A:$C,3,0) -> #N/A
A17: 12 | D17: =VLOOKUP($B17,ma!$A:$B,2,0) -> #N/A | K17: 1 | L17: =VLOOKUP($B17,ma!$A:$C,3,0) -> #N/A | M17: =VLOOKUP($B17,ma!$A:$C,3,0) -> #N/A
A18: 13 | D18: =VLOOKUP($B18,ma!$A:$B,2,0) -> #N/A | K18: 1 | L18: =VLOOKUP($B18,ma!$A:$C,3,0) -> #N/A | M18: =VLOOKUP($B18,ma!$A:$C,3,0) -> #N/A
A19: 14 | D19: =VLOOKUP($B19,ma!$A:$B,2,0) -> #N/A | K19: 1 | L19: =VLOOKUP($B19,ma!$A:$C,3,0) -> #N/A | M19: =VLOOKUP($B19,ma!$A:$C,3,0) -> #N/A
A20: 15 | D20: =VLOOKUP($B20,ma!$A:$B,2,0) -> #N/A | K20: 1 | L20: =VLOOKUP($B20,ma!$A:$C,3,0) -> #N/A | M20: =VLOOKUP($B20,ma!$A:$C,3,0) -> #N/A
A21: 16 | D21: =VLOOKUP($B21,ma!$A:$B,2,0) -> #N/A | K21: 1 | L21: =VLOOKUP($B21,ma!$A:$C,3,0) -> #N/A | M21: =VLOOKUP($B21,ma!$A:$C,3,0) -> #N/A
A22: 17 | D22: =VLOOKUP($B22,ma!$A:$B,2,0) -> #N/A | K22: 1 | L22: =VLOOKUP($B22,ma!$A:$C,3,0) -> #N/A | M22: =VLOOKUP($B22,ma!$A:$C,3,0) -> #N/A
A23: 18 | D23: =VLOOKUP($B23,ma!$A:$B,2,0) -> #N/A | K23: 1 | L23: =VLOOKUP($B23,ma!$A:$C,3,0) -> #N/A | M23: =VLOOKUP($B23,ma!$A:$C,3,0) -> #N/A
A24: 19 | D24: =VLOOKUP($B24,ma!$A:$B,2,0) -> #N/A | K24: 1 | L24: =VLOOKUP($B24,ma!$A:$C,3,0) -> #N/A | M24: =VLOOKUP($B24,ma!$A:$C,3,0) -> #N/A
A25: 20 | D25: =VLOOKUP($B25,ma!$A:$B,2,0) -> #N/A | K25: 1 | L25: =VLOOKUP($B25,ma!$A:$C,3,0) -> #N/A | M25: =VLOOKUP($B25,ma!$A:$C,3,0) -> #N/A
A26: 21 | D26: =VLOOKUP($B26,ma!$A:$B,2,0) -> #N/A | K26: 1 | L26: =VLOOKUP($B26,ma!$A:$C,3,0) -> #N/A | M26: =VLOOKUP($B26,ma!$A:$C,3,0) -> #N/A
A27: 22 | D27: =VLOOKUP($B27,ma!$A:$B,2,0) -> #N/A | K27: 1 | L27: =VLOOKUP($B27,ma!$A:$C,3,0) -> #N/A | M27: =VLOOKUP($B27,ma!$A:$C,3,0) -> #N/A
... A37: 32 | D37: =VLOOKUP($B37,ma!$A:$B,2,0) -> #N/A | K37: 1 | L37: =VLOOKUP($B37,ma!$A:$C,3,0) -> #N/A | M37: =VLOOKUP($B37,ma!$A:$C,3,0) -> #N/A
A38: 33 | D38: =VLOOKUP($B38,ma!$A:$B,2,0) -> #N/A | K38: 1 | L38: =VLOOKUP($B38,ma!$A:$C,3,0) -> #N/A | M38: =VLOOKUP($B38,ma!$A:$C,3,0) -> #N/A | P38: =SUM(P6:P37) -> 445110000
A39: 34 | D39: =VLOOKUP($B39,ma!$A:$B,2,0) -> #N/A | K39: 1 | L39: =VLOOKUP($B39,ma!$A:$C,3,0) -> #N/A | M39: =VLOOKUP($B39,ma!$A:$C,3,0) -> #N/A
A40: 35 | D40: =VLOOKUP($B40,ma!$A:$B,2,0) -> #N/A | K40: 1 | L40: =VLOOKUP($B40,ma!$A:$C,3,0) -> #N/A | M40: =VLOOKUP($B40,ma!$A:$C,3,0) -> #N/A | O40: MUA XE | P40: =P38 -> 445110000
A41: 36 | D41: =VLOOKUP($B41,ma!$A:$B,2,0) -> #N/A | K41: 1 | L41: =VLOOKUP($B41,ma!$A:$C,3,0) -> #N/A | M41: =VLOOKUP($B41,ma!$A:$C,3,0) -> #N/A | O41: THUẬN 50% | P41: =P40/2 -> 222555000
A42: 37 | D42: =VLOOKUP($B42,ma!$A:$B,2,0) -> #N/A | K42: 1 | L42: =VLOOKUP($B42,ma!$A:$C,3,0) -> #N/A | M42: =VLOOKUP($B42,ma!$A:$C,3,0) -> #N/A | O42: KIM 50% | P42: =P40/2 -> 222555000
C43: Tổng cộng : | F43: 176.9 | G43: =SUM(G6:G42) -> 0 | I43: =SUM(I6:I42) -> 900000 | K43: 37 | M43: =SUM(M6:M42) -> #N/A
C44: Doanh Thu | D44: 30,100,000
C45: Chi Phí | D45: =G43+I43 -> 900000 | G45: doanh thu 01/2025
C46: Lương | D46: 7,800,000 | G46: 45658
G47: 45689 | H47: 12050000
C48: BHXH | D48: 1,100,000 | G48: 45717 | H48: 13090000
C49: Còn Lại | D49: 12,108,000 | G49: 45748 | H49: 12140000
...

Sheet 50H-87442
C1: BẢNG KÊ 50H-87442
C2: 45930
C3: Tên : | E3: SỐ XE : | I3: 50H-87442
D4: #N/A | L4: #N/A
A5: STT | B5: Mã | C5: Ngày | D5: Nơi giao | E5: Đổ Dầu | F5: SỐ KM | G5: CẦU ĐƯỜNG | H5: Ghi chú | I5: C.phí c.xe | J5: ghi chú | K5: TÀI | L5: Đơn giá | M5: Thành tiền | O5: 50H-87442 ( 51C-85202 ) mua ngày 26/05/2025
A6: 1 | D6: =VLOOKUP($B6,ma!$A:$B,2,0) -> #N/A | K6: 1 | L6: =VLOOKUP($B6,ma!$A:$C,3,0) -> #N/A | M6: =VLOOKUP($B6,ma!$A:$C,3,0) -> #N/A | O6: NGÀY | P6: SỐ KM | Q6: VẬT TƯ | R6: GIÁ TIỀN | S6: CÔNG THỢ | T6: THÀNH TIỀN | U6: =SUM(U7:U115) -> 316040000 | V6: =U6/2 -> 158020000
A7: 2 | D7: =VLOOKUP($B7,ma!$A:$B,2,0) -> #N/A | K7: 1 | L7: =VLOOKUP($B7,ma!$A:$C,3,0) -> #N/A | M7: =VLOOKUP($B7,ma!$A:$C,3,0) -> #N/A | O7: 45803 | Q7: MUA XE | R7: 295000000 | T7: =SUM(R7:S7) -> 295000000 | U7: =T7 -> 295000000
A8: 3 | D8: =VLOOKUP($B8,ma!$A:$B,2,0) -> #N/A | K8: 1 | L8: =VLOOKUP($B8,ma!$A:$C,3,0) -> #N/A | M8: =VLOOKUP($B8,ma!$A:$C,3,0) -> #N/A | O8: 45803 | Q8: Móc lỗ thùng cột hàng | S8: 600000 | T8: =SUM(R8:S8) -> 600000 | U8: =T8 -> 600000
A9: 4 | D9: =VLOOKUP($B9,ma!$A:$B,2,0) -> #N/A | I9: 900000 | J9: bãi xe lê văn lương | K9: 1 | L9: =VLOOKUP($B9,ma!$A:$C,3,0) -> #N/A | M9: =VLOOKUP($B9,ma!$A:$C,3,0) -> #N/A | Q9: thuế trước bạ | R9: 3145000 | T9: 3150000
A10: 5 | D10: =VLOOKUP($B10,ma!$A:$B,2,0) -> #N/A | K10: 1 | L10: =VLOOKUP($B10,ma!$A:$C,3,0) -> #N/A | M10: =VLOOKUP($B10,ma!$A:$C,3,0) -> #N/A | Q10: Làm giấy tờ | R10: 5000000 | T10: =SUM(R10:S10) -> 5000000
A11: 6 | D11: =VLOOKUP($B11,ma!$A:$B,2,0) -> #N/A | K11: 1 | L11: =VLOOKUP($B11,ma!$A:$C,3,0) -> #N/A | M11: =VLOOKUP($B11,ma!$A:$C,3,0) -> #N/A | P11: menmen | Q11: đóng inox biển số | R11: 500000 | T11: =SUM(R11:S11) -> 500000
A12: 7 | D12: =VLOOKUP($B12,ma!$A:$B,2,0) -> #N/A | K12: 1 | L12: =VLOOKUP($B12,ma!$A:$C,3,0) -> #N/A | M12: =VLOOKUP($B12,ma!$A:$C,3,0) -> #N/A | Q12: xét xe + cò xét xe | R12: 1200000 | T12: =SUM(R12:S12) -> 1200000
A13: 8 | D13: =VLOOKUP($B13,ma!$A:$B,2,0) -> #N/A | K13: 1 | L13: =VLOOKUP($B13,ma!$A:$C,3,0) -> #N/A | M13: =VLOOKUP($B13,ma!$A:$C,3,0) -> #N/A | Q13: gắn định vị | R13: 2420000 | T13: =SUM(R13:S13) -> 2420000
A14: 9 | D14: =VLOOKUP($B14,ma!$A:$B,2,0) -> #N/A | K14: 1 | L14: =VLOOKUP($B14,ma!$A:$C,3,0) -> #N/A | M14: =VLOOKUP($B14,ma!$A:$C,3,0) -> #N/A | Q14: MUA KÈN XE | R14: 400000 | T14: =SUM(R14:S14) -> 400000
A15: 10 | D15: =VLOOKUP($B15,ma!$A:$B,2,0) -> #N/A | K15: 1 | L15: =VLOOKUP($B15,ma!$A:$C,3,0) -> #N/A | M15: =VLOOKUP($B15,ma!$A:$C,3,0) -> #N/A | Q15: Bao tay ,tựa lưng | R15: 600000 | T15: =SUM(R15:S15) -> 600000
A16: 11 | D16: =VLOOKUP($B16,ma!$A:$B,2,0) -> #N/A | K16: 1 | L16: =VLOOKUP($B16,ma!$A:$C,3,0) -> #N/A | M16: =VLOOKUP($B16,ma!$A:$C,3,0) -> #N/A | Q16: PHÙ HIỆU XE | R16: 500000 | T16: =SUM(R16:S16) -> 500000
A17: 12 | D17: =VLOOKUP($B17,ma!$A:$B,2,0) -> #N/A | K17: 1 | L17: =VLOOKUP($B17,ma!$A:$C,3,0) -> #N/A | M17: =VLOOKUP($B17,ma!$A:$C,3,0) -> #N/A | T17: =SUM(T9:T16) -> 13770000 | U17: =T17 -> 13770000
A18: 13 | D18: =VLOOKUP($B18,ma!$A:$B,2,0) -> #N/A | K18: 1 | L18: =VLOOKUP($B18,ma!$A:$C,3,0) -> #N/A | M18: =VLOOKUP($B18,ma!$A:$C,3,0) -> #N/A | O18: 45823 | P18: 50H-87442 | Q18: Thay 6 cúp ben bánh 50*6 | R18: 300000 | T18: =SUM(R18:S18) -> 300000
A19: 14 | D19: =VLOOKUP($B19,ma!$A:$B,2,0) -> #N/A | K19: 1 | L19: =VLOOKUP($B19,ma!$A:$C,3,0) -> #N/A | M19: =VLOOKUP($B19,ma!$A:$C,3,0) -> #N/A | Q19: thay 2 phốt bánh sau 120*2 | R19: 240000 | T19: =SUM(R19:S19) -> 240000
A20: 15 | D20: =VLOOKUP($B20,ma!$A:$B,2,0) -> #N/A | K20: 1 | L20: =VLOOKUP($B20,ma!$A:$C,3,0) -> #N/A | M20: =VLOOKUP($B20,ma!$A:$C,3,0) -> #N/A | Q20: thay bạc đạn bánh sau | R20: 480000 | T20: =SUM(R20:S20) -> 480000
A21: 16 | D21: =VLOOKUP($B21,ma!$A:$B,2,0) -> #N/A | K21: 1 | L21: =VLOOKUP($B21,ma!$A:$C,3,0) -> #N/A | M21: =VLOOKUP($B21,ma!$A:$C,3,0) -> #N/A | Q21: mở bò VÔ BÁNH | R21: 200000 | T21: =SUM(R21:S21) -> 200000
A22: 17 | D22: =VLOOKUP($B22,ma!$A:$B,2,0) -> #N/A | K22: 1 | L22: =VLOOKUP($B22,ma!$A:$C,3,0) -> #N/A | M22: =VLOOKUP($B22,ma!$A:$C,3,0) -> #N/A | Q22: thay lọc nhớt | R22: 160000 | T22: =SUM(R22:S22) -> 160000
A23: 18 | D23: =VLOOKUP($B23,ma!$A:$B,2,0) -> #N/A | K23: 1 | L23: =VLOOKUP($B23,ma!$A:$C,3,0) -> #N/A | M23: =VLOOKUP($B23,ma!$A:$C,3,0) -> #N/A | Q23: thay lọc dầu | R23: 220000 | T23: =SUM(R23:S23) -> 220000
A24: 19 | D24: =VLOOKUP($B24,ma!$A:$B,2,0) -> #N/A | K24: 1 | L24: =VLOOKUP($B24,ma!$A:$C,3,0) -> #N/A | M24: =VLOOKUP($B24,ma!$A:$C,3,0) -> #N/A | Q24: làm ắc cần số + vô nhớt dây số | R24: 300000 | T24: =SUM(R24:S24) -> 300000
A25: 20 | D25: =VLOOKUP($B25,ma!$A:$B,2,0) -> #N/A | K25: 1 | L25: =VLOOKUP($B25,ma!$A:$C,3,0) -> #N/A | M25: =VLOOKUP($B25,ma!$A:$C,3,0) -> #N/A | Q25: công làm | S25: 1300000 | T25: =SUM(R25:S25) -> 1300000
A26: 21 | D26: =VLOOKUP($B26,ma!$A:$B,2,0) -> #N/A | K26: 1 | L26: =VLOOKUP($B26,ma!$A:$C,3,0) -> #N/A | M26: =VLOOKUP($B26,ma!$A:$C,3,0) -> #N/A | Q26: mua nhớt máy 80*9 | R26: 720000 | T26: =SUM(R26:S26) -> 720000
A27: 22 | D27: =VLOOKUP($B27,ma!$A:$B,2,0) -> #N/A | K27: 1 | L27: =VLOOKUP($B27,ma!$A:$C,3,0) -> #N/A | M27: =VLOOKUP($B27,ma!$A:$C,3,0) -> #N/A | Q27: công thợ chỉnh pét dầu | S27: 600000 | T27: =SUM(R27:S27) -> 600000
A28: 23 | D28: =VLOOKUP($B28,ma!$A:$B,2,0) -> #N/A | K28: 1 | L28: =VLOOKUP($B28,ma!$A:$C,3,0) -> #N/A | M28: =VLOOKUP($B28,ma!$A:$C,3,0) -> #N/A | T28: =SUM(T18:T27) -> 4520000 | U28: =T28 -> 4520000
A29: 24 | D29: =VLOOKUP($B29,ma!$A:$B,2,0) -> #N/A | K29: 1 | L29: =VLOOKUP($B29,ma!$A:$C,3,0) -> #N/A | M29: =VLOOKUP($B29,ma!$A:$C,3,0) -> #N/A | O29: 45830 | P29: Hùng gara | Q29: thay chốt chặn cửa | R29: 800000 | T29: =SUM(R29:S29) -> 800000
A30: 25 | D30: =VLOOKUP($B30,ma!$A:$B,2,0) -> #N/A | K30: 1 | L30: =VLOOKUP($B30,ma!$A:$C,3,0) -> #N/A | M30: =VLOOKUP($B30,ma!$A:$C,3,0) -> #N/A | Q30: chỉnh cửa + công lắp | R30: 600000 | S30: 400000 | T30: =SUM(R30:S30) -> 1000000
A31: 26 | D31: =VLOOKUP($B31,ma!$A:$B,2,0) -> #N/A | K31: 1 | L31: =VLOOKUP($B31,ma!$A:$C,3,0) -> #N/A | M31: =VLOOKUP($B31,ma!$A:$C,3,0) -> #N/A | Q31: gắn miếng che | R31: 100000 | T31: =SUM(R31:S31) -> 100000 | U31: =SUM(T29:T31) -> 1900000
A32: 27 | D32: =VLOOKUP($B32,ma!$A:$B,2,0) -> #N/A | K32: 1 | L32: =VLOOKUP($B32,ma!$A:$C,3,0) -> #N/A | M32: =VLOOKUP($B32,ma!$A:$C,3,0) -> #N/A | O32: 45846 | Q32: mua đầu đĩa | R32: 250000 | T32: =SUM(R32:S32) -> 250000 | U32: =T32 -> 250000
A33: 28 | D33: =VLOOKUP($B33,ma!$A:$B,2,0) -> #N/A | K33: 1 | L33: =VLOOKUP($B33,ma!$A:$C,3,0) -> #N/A | M33: =VLOOKUP($B33,ma!$A:$C,3,0) -> #N/A | T33: =SUM(R33:S33) -> 0
A34: 29 | D34: =VLOOKUP($B34,ma!$A:$B,2,0) -> #N/A | K34: 1 | L34: =VLOOKUP($B34,ma!$A:$C,3,0) -> #N/A | M34: =VLOOKUP($B34,ma!$A:$C,3,0) -> #N/A | T34: =SUM(R34:S34) -> 0
A35: 30 | D35: =VLOOKUP($B35,ma!$A:$B,2,0) -> #N/A | K35: 1 | L35: =VLOOKUP($B35,ma!$A:$C,3,0) -> #N/A | M35: =VLOOKUP($B35,ma!$A:$C,3,0) -> #N/A | T35: =SUM(R35:S35) -> 0
A36: 31 | D36: =VLOOKUP($B36,ma!$A:$B,2,0) -> #N/A | K36: 1 | L36: =VLOOKUP($B36,ma!$A:$C,3,0) -> #N/A | M36: =VLOOKUP($B36,ma!$A:$C,3,0) -> #N/A | T36: =SUM(R36:S36) -> 0
A37: 32 | D37: =VLOOKUP($B37,ma!$A:$B,2,0) -> #N/A | K37: 1 | L37: =VLOOKUP($B37,ma!$A:$C,3,0) -> #N/A | M37: =VLOOKUP($B37,ma!$A:$C,3,0) -> #N/A | T37: =SUM(R37:S37) -> 0
C38: Tổng cộng : | F38: 176.9 | G38: =SUM(G6:G37) -> 0 | I38: =SUM(I6:I37) -> 900000 | K38: 32 | M38: =SUM(M6:M37) -> #N/A | P38: =SUM(P6:P37) -> 0 | T38: =SUM(R38:S38) -> 0
C39: Doanh Thu | D39: 25,400,000
C40: Chi Phí | D40: =G38+I38 -> 900000 | G40: doanh thu 01/2025
...
