Workbook

Sheet xe
A1: MA | B1: SỐ XE
A3: B Tâm | B3: 50H-70216
A4: F Y | B4: 50H-55116
A5: Y THANH | B5: 50H-69501
A6: Q HẢI | B6: 50H-64316
A7: N QUỐC | B7: 50H-50999
A8: Ư LỪA | B8: 50E-164,61
A9: V VŨ | B9: 51H -88294
A10: C SƠN | B10: 50H-74619
A11: A LỢI | B11: 50H 87442
A12: W HIẾU | B12: 50H-64470
A13: M HƯNG | B13: 50H-66445
... A31: L11 HẢI | B31: 50H-69717

Sheet ma
A1: MA | B1: TUYEN | C1: OTO 5
A2: NT | B2: NHA TRANG
A3: NHOA | B3: NINH HÒA
A4: CR | B4: CAM RANH
A5: CLANH | B5: CAO LÃNH | C5: 280000
A6: LKX | B6: LONG KHÁNH XÁ | C6: 244000
A7: LKP | B7: LONG KHÁNH PALLET | C7: 244000
A9: AJLH | B9: AJ LONG HẬU | C9: 600000
A10: ndfc | B10: Chuyển Hàng ndfc | C10: 410000
A11: N6 | B11: NDFC 6 CHUYẾN | C11: 300000
A12: calo | B12: Chuyển hàng Calofic | C12: 180000
A13: CL1 | B13: CH Calofic 13c | C13: 140000
A14: clun | B14: CALOFIC - UNI ( xe nhỏ ) | C14: 300000
A15: cluni | B15: CALOFIC - UNI ( xe lớn ) | C15: 400000
A16: CLMXL | B16: COOP LÊ MINH XUÂN ( XE LỚN ) | C16: 200000
A17: UNCLG | B17: UNI - CALOFIC ( CHUYỂN GẠO ) | C17: 100000
... A46: TP2 | B46: TP2 GÒ VẤP | C46: 800000
A47: NL | B47: NGỌC LAN L.AN
A48: THTDH | B48: TÂN HÙNG THÁI ĐỨC HOÀ | C48: 210000
A49: KVBC | B49: KIẾN VƯƠNG BÌNH CHÁNH | C49: 190000
A50: mifa | B50: MIFA TÂN TẠO | C50: 200000
A51: mf | B51: MIFA TÂN TẠO XE NHỎ ( KBX ) | C51: 800000
A52: BP | B52: BÌNH PHƯỚC
A53: BT | B53: BÌNH TRÍ | C53: 212000
A54: BTAY | B54: BÌNH TÂY | C54: 220000
A55: BHCDL | B55: BHX CẦN ĐƯƠC XL | C55: 210000
A56: MKR | B56: MAKARA | C56: 200000
A57: TN | B57: TÂY NINH
A58: VL | B58: PHÔI VIỆT LONG
A59: SD | B59: SA ĐÉC
A60: TNOTX | B60: THỐT NỐT XÁ | C60: 370000
A61: CD | B61: CHÂU ĐỐC
A62: HG | B62: HẬU GAING
A63: HT | B63: HÀ TIÊN
A64: PQ | B64: PHÚ QUỐC
A65: NE3 | B65: NESTLE 3-7 | C65: 442000
A66: NE7 | B66: NESTLE 7-10 | C66: 393000
A67: NE10 | B67: NESTLE >10 | C67: 363000
A68: NDNA | B68: NDFC - NAIC BẾN LỨC | C68: 2400000
A69: NAUN | B69: NAIC -UNI | C69: 1800000
...

Sheet XE NHỎ
D1: CÔNG TNHH DV VT PHÚ PHÁT
D2: 165 Đỗ Thị Lời, P11, Q3, TP. HCM.
D3: CÔNG TNHH DV VT PHÚ PHÁT
D4: 46141 | Q4: LƯU
D5: Tên : | J5: Số xe :
K6: P | P6: #N/A
A7: F | B7: TÊN | D7: Ngày | E7: Số xe | F7: Nơi giao | H7: Cđường | I7: Cđường | J7: ghi chú | K7: TẤN | L7: B.XẾP | M7: C.phí | N7: ghi chú | O7: TÀI | P7: Đơn giá | Q7: Thành tiền
A8: 1 | B8: em | C8: F Y | D8: 46174 | E8: =VLOOKUP($C8,xe!$A:$B,2,0) -> 50H-55116 | F8: =VLOOKUP($B8,ma!$A:$B,2,0) -> E MART P.V.TRỊ | G8: 10594 | H8: 2/6 | J8: UNI | K8: 1.2 | L8: =K8*100000 -> 120000 | O8: 1 | P8: =VLOOKUP($B8,ma!$A:$C,3,0) -> 800000 | Q8: 880000 | R8: 0.1
A9: =A8+1 -> 2 | B9: em | C9: N QUỐC | D9: 46174 | E9: =VLOOKUP($C9,xe!$A:$B,2,0) -> 50H-50999 | F9: =VLOOKUP($B9,ma!$A:$B,2,0) -> E MART P.V.TRỊ | G9: 10596+10595 | H9: 2/6 | J9: UNI | K9: 1.2 | L9: =K9*100000 -> 120000 | O9: 1 | P9: =VLOOKUP($B9,ma!$A:$C,3,0) -> 800000 | Q9: 880000 | R9: 0.1
A10: =A9+1 -> 3 | B10: em | C10: W HIẾU | D10: 46174 | E10: =VLOOKUP($C10,xe!$A:$B,2,0) -> 50H-64470 | F10: =VLOOKUP($B10,ma!$A:$B,2,0) -> E MART P.V.TRỊ | G10: 10597 | H10: 2/6 | J10: UNI | K10: 1.2 | L10: =K10*100000 -> 120000 | O10: 1 | P10: =VLOOKUP($B10,ma!$A:$C,3,0) -> 800000 | Q10: 880000 | R10: 0.1
A11: =A10+1 -> 4 | B11: kfc | C11: V VŨ | D11: 46174 | E11: =VLOOKUP($C11,xe!$A:$B,2,0) -> 51H -88294 | F11: =VLOOKUP($B11,ma!$A:$B,2,0) -> KFC GÒ VẤP ( K BX ) | G11: 88767 | H11: 2/6 | J11: NDFC | K11: 2 | L11: 150000 | O11: 1 | P11: =VLOOKUP($B11,ma!$A:$C,3,0) -> 800000 | Q11: 880000 | R11: 0.1
A12: =A11+1 -> 5 | B12: kfc | C12: Y THANH | D12: 46174 | E12: =VLOOKUP($C12,xe!$A:$B,2,0) -> 50H-69501 | F12: =VLOOKUP($B12,ma!$A:$B,2,0) -> KFC GÒ VẤP ( K BX ) | G12: 88772 | H12: 2/6 | J12: NDFC | K12: 2 | L12: 150000 | O12: 1 | P12: =VLOOKUP($B12,ma!$A:$C,3,0) -> 800000 | Q12: 880000 | R12: 0.1
A13: =A12+1 -> 6 | B13: kfc | C13: Q HẢI | D13: 46174 | E13: =VLOOKUP($C13,xe!$A:$B,2,0) -> 50H-64316 | F13: =VLOOKUP($B13,ma!$A:$B,2,0) -> KFC GÒ VẤP ( K BX ) | G13: 88757 | H13: 2/6 | J13: NDFC | K13: 2 | L13: 150000 | O13: 1 | P13: =VLOOKUP($B13,ma!$A:$C,3,0) -> 800000 | Q13: 880000 | R13: 0.1
A14: =A13+1 -> 7 | B14: kfc | C14: T ANH | D14: 46174 | E14: =VLOOKUP($C14,xe!$A:$B,2,0) -> 50H-54580 | F14: =VLOOKUP($B14,ma!$A:$B,2,0) -> KFC GÒ VẤP ( K BX ) | G14: 88770 | H14: 2/6 | J14: NDFC | K14: 2 | L14: 150000 | O14: 1 | P14: =VLOOKUP($B14,ma!$A:$C,3,0) -> 800000 | Q14: 880000 | R14: 0.1
A15: =A14+1 -> 8 | B15: kfc | C15: M HƯNG | D15: 46174 | E15: =VLOOKUP($C15,xe!$A:$B,2,0) -> 50H-66445 | F15: =VLOOKUP($B15,ma!$A:$B,2,0) -> KFC GÒ VẤP ( K BX ) | G15: 88761 | H15: 2/6 | J15: NDFC | K15: 2 | L15: 150000 | O15: 1 | P15: =VLOOKUP($B15,ma!$A:$C,3,0) -> 800000 | Q15: 880000 | R15: 0.1
A16: =A15+1 -> 9 | B16: af | C16: A DUNG | D16: 46174 | E16: =VLOOKUP($C16,xe!$A:$B,2,0) -> #N/A | F16: =VLOOKUP($B16,ma!$A:$B,2,0) -> ANFOOD Q12 ( K BX ) | G16: 88702 | H16: 2/6 | K16: 2 | O16: 1 | P16: =VLOOKUP($B16,ma!$A:$C,3,0) -> 800000 | Q16: 880000 | R16: 0.1
A17: =A16+1 -> 10 | B17: af | C17: Z | D17: 46174 | E17: =VLOOKUP($C17,xe!$A:$B,2,0) -> #N/A | F17: =VLOOKUP($B17,ma!$A:$B,2,0) -> ANFOOD Q12 ( K BX ) | G17: 10600+88787 | H17: 2/6 | K17: 2 | O17: 1 | P17: =VLOOKUP($B17,ma!$A:$C,3,0) -> 800000 | Q17: 880000 | R17: 0.1
A18: =A17+1 -> 11 | B18: sht | C18: THUẬN | D18: 46174 | E18: =VLOOKUP($C18,xe!$A:$B,2,0) -> #N/A | F18: =VLOOKUP($B18,ma!$A:$B,2,0) -> SONG HỒNG TÂN ( KBX ) | G18: 88766 | H18: 4/6 | J18: MCC | K18: 1 | O18: 1 | P18: =VLOOKUP($B18,ma!$A:$C,3,0) -> 900000 | Q18: 990000 | R18: 0.1
A19: =A18+1 -> 12 | B19: tp2 | C19: E1 | D19: 46174 | E19: =VLOOKUP($C19,xe!$A:$B,2,0) -> #N/A | F19: =VLOOKUP($B19,ma!$A:$B,2,0) -> TP2 GÒ VẤP | G19: 7382 | H19: 2/6 | J19: XUẤT UNI | O19: 1 | P19: =VLOOKUP($B19,ma!$A:$C,3,0) -> 800000 | Q19: 880000 | R19: 0.1
A20: =A19+1 -> 13 | B20: tp2 | C20: Y1 | D20: 46174 | E20: =VLOOKUP($C20,xe!$A:$B,2,0) -> #N/A | F20: =VLOOKUP($B20,ma!$A:$B,2,0) -> TP2 GÒ VẤP | G20: 7391 | H20: 2/6 | J20: XUẤT UNI | O20: 1 | P20: =VLOOKUP($B20,ma!$A:$C,3,0) -> 800000 | Q20: 880000 | R20: 0.1
A21: =A20+1 -> 14 | B21: tp2 | C21: U THANH | D21: 46174 | E21: =VLOOKUP($C21,xe!$A:$B,2,0) -> #N/A | F21: =VLOOKUP($B21,ma!$A:$B,2,0) -> TP2 GÒ VẤP | G21: 7389 | H21: 2/6 | J21: XUẤT UNI | O21: 1 | P21: =VLOOKUP($B21,ma!$A:$C,3,0) -> 800000 | Q21: 880000 | R21: 0.1
A22: =A21+1 -> 15 | B22: tp2 | C22: I THI | D22: 46174 | E22: =VLOOKUP($C22,xe!$A:$B,2,0) -> #N/A | F22: =VLOOKUP($B22,ma!$A:$B,2,0) -> TP2 GÒ VẤP | G22: 7379 | H22: 2/6 | J22: XUẤT UNI | O22: 1 | P22: =VLOOKUP($B22,ma!$A:$C,3,0) -> 800000 | Q22: 880000 | R22: 0.1
A23: =A22+1 -> 16 | B23: tp2 | C23: P VŨ | D23: 46174 | E23: =VLOOKUP($C23,xe!$A:$B,2,0) -> #N/A | F23: =VLOOKUP($B23,ma!$A:$B,2,0) -> TP2 GÒ VẤP | G23: 7386 | H23: 5/6 | J23: XUẤT UNI | O23: 1 | P23: =VLOOKUP($B23,ma!$A:$C,3,0) -> 800000 | Q23: 880000 | R23: 0.1
A24: =A23+1 -> 17 | B24: dpqt | C24: E | D24: 46174 | E24: =VLOOKUP($C24,xe!$A:$B,2,0) -> #N/A | F24: =VLOOKUP($B24,ma!$A:$B,2,0) -> DƯỢC PHẨM QUỐC TẾ ( KBX ) | G24: 88777 | H24: 5/6 | K24: 1.6 | O24: 1 | P24: =VLOOKUP($B24,ma!$A:$C,3,0) -> 800000 | Q24: 880000 | R24: 0.1
A25: =A24+1 -> 18 | B25: dpqt | C25: X1 | D25: 46174 | E25: =VLOOKUP($C25,xe!$A:$B,2,0) -> #N/A | F25: =VLOOKUP($B25,ma!$A:$B,2,0) -> DƯỢC PHẨM QUỐC TẾ ( KBX ) | G25: 88779 | H25: 5/6 | K25: 1.6 | O25: 1 | P25: =VLOOKUP($B25,ma!$A:$C,3,0) -> 800000 | Q25: 880000 | R25: 0.1
A26: =A25+1 -> 19 | B26: dpqt | C26: C SƠN | D26: 46174 | E26: =VLOOKUP($C26,xe!$A:$B,2,0) -> 50H-74619 | F26: =VLOOKUP($B26,ma!$A:$B,2,0) -> DƯỢC PHẨM QUỐC TẾ ( KBX ) | G26: 88775 | H26: 5/6 | K26: 1.8 | L26: 50000 | O26: 1 | P26: =VLOOKUP($B26,ma!$A:$C,3,0) -> 800000 | Q26: 880000 | R26: 0.1
A27: =A26+1 -> 20 | B27: ssg | C27: thuận | D27: 46174 | E27: =VLOOKUP($C27,xe!$A:$B,2,0) -> #N/A | F27: =VLOOKUP($B27,ma!$A:$B,2,0) -> SATRA SÀI GÒN | G27: 89022 | H27: 4/6 | K27: 1 | L27: =K27*50000 -> 50000 | O27: 1 | P27: =VLOOKUP($B27,ma!$A:$C,3,0) -> 800000 | Q27: 880000 | R27: 0.1
A28: =A27+1 -> 21 | B28: bcmd | C28: LONG | D28: 46174 | E28: =VLOOKUP($C28,xe!$A:$B,2,0) -> 50H-55443 | F28: =VLOOKUP($B28,ma!$A:$B,2,0) -> BC MIỀN ĐÔNG | G28: 88773+88774+11000+10599 | H28: 2/6 | K28: 2 | L28: =K28*50000 -> 100000 | O28: 1 | P28: =VLOOKUP($B28,ma!$A:$C,3,0) -> 800000 | Q28: 880000 | R28: 0.1
A29: =A28+1 -> 22 | B29: ntru | C29: A LỢI | D29: 46174 | E29: =VLOOKUP($C29,xe!$A:$B,2,0) -> 50H 87442 | F29: =VLOOKUP($B29,ma!$A:$B,2,0) -> NGUYỄN TRƯƠNG | G29: 88710 | H29: 2/6 | K29: 1.2 | L29: =K29*50000 -> 60000 | O29: 1 | P29: =VLOOKUP($B29,ma!$A:$C,3,0) -> 800000 | Q29: 880000 | R29: 0.1
A30: =A29+1 -> 23 | B30: ha | C30: O VƯƠNG | D30: 46174 | E30: =VLOOKUP($C30,xe!$A:$B,2,0) -> 50H-63174 | F30: =VLOOKUP($B30,ma!$A:$B,2,0) -> HỒNG Á ( K BX ) | G30: 88704 | H30: 2/6 | L30: 50000 | O30: 1 | P30: =VLOOKUP($B30,ma!$A:$C,3,0) -> 800000 | Q30: 880000 | R30: 0.1
A31: =A30+1 -> 24 | B31: spm | C31: Ư LỪA | D31: 46174 | E31: =VLOOKUP($C31,xe!$A:$B,2,0) -> 50E-164,61 | F31: =VLOOKUP($B31,ma!$A:$B,2,0) -> SPM TÂN TẠO | G31: 88719 | H31: 2/6 | K31: 1.8 | L31: =K31*50000 -> 90000 | O31: 1 | P31: =VLOOKUP($B31,ma!$A:$C,3,0) -> 800000 | Q31: 880000 | R31: 0.1
A32: =A31+1 -> 25 | B32: vhq8 | C32: B TÂM | D32: 46174 | E32: =VLOOKUP($C32,xe!$A:$B,2,0) -> 50H-70216 | F32: =VLOOKUP($B32,ma!$A:$B,2,0) -> VĂN HẬU Q8 ( K BX ) | G32: R | H32: R | K32: 2.2 | L32: 50000 | O32: 1 | P32: =VLOOKUP($B32,ma!$A:$C,3,0) -> 800000 | Q32: 880000 | R32: 0.1
A33: =A32+1 -> 26 | B33: agr | C33: R THI | D33: 46174 | E33: =VLOOKUP($C33,xe!$A:$B,2,0) -> 50H-55161 | F33: =VLOOKUP($B33,ma!$A:$B,2,0) -> Agrex SG | G33: 88944 | H33: 2/6 | K33: 1.6 | L33: =K33*50000 -> 80000 | O33: 1 | P33: =VLOOKUP($B33,ma!$A:$C,3,0) -> 800000 | Q33: 880000 | R33: 0.1
A34: =A33+1 -> 27 | B34: agr | C34: R THI | D34: 46174 | E34: =VLOOKUP($C34,xe!$A:$B,2,0) -> 50H-55161 | F34: =VLOOKUP($B34,ma!$A:$B,2,0) -> Agrex SG | G34: 88706 | H34: 2/6 | K34: 1.6 | L34: =K34*50000 -> 80000 | O34: 1 | P34: =VLOOKUP($B34,ma!$A:$C,3,0) -> 800000 | Q34: 880000 | R34: 0.1
A35: =A34+1 -> 28 | B35: vnhp | C35: ư lừa | D35: 46174 | E35: =VLOOKUP($C35,xe!$A:$B,2,0) -> 50E-164,61 | F35: =VLOOKUP($B35,ma!$A:$B,2,0) -> VỊ NGỌT HAPPY ( K BX ) | G35: 88948 | H35: 2/6 | K35: 1.2 | L35: 50000 | O35: 1 | P35: =VLOOKUP($B35,ma!$A:$C,3,0) -> 800000 | Q35: 880000 | R35: 0.1
A36: =A35+1 -> 29 | B36: vnhp | C36: a lợi | D36: 46174 | E36: =VLOOKUP($C36,xe!$A:$B,2,0) -> 50H 87442 | F36: =VLOOKUP($B36,ma!$A:$B,2,0) -> VỊ NGỌT HAPPY ( K BX ) | G36: 88947 | H36: 2/6 | K36: 1.2 | L36: 50000 | O36: 1 | P36: =VLOOKUP($B36,ma!$A:$C,3,0) -> 800000 | Q36: 880000 | R36: 0.1
A37: =A36+1 -> 30 | B37: bnb | C37: O VƯƠNG | D37: 46174 | E37: =VLOOKUP($C37,xe!$A:$B,2,0) -> 50H-63174 | F37: =VLOOKUP($B37,ma!$A:$B,2,0) -> BHX NHÀ BÈ | G37: 88892+88905 | H37: 2/6 | J37: NDFC | K37: 1.8 | L37: 180000 | O37: 1 | P37: =VLOOKUP($B37,ma!$A:$C,3,0) -> 400000 | Q37: 440000 | R37: 0.1
A38: =A37+1 -> 31 | B38: bnb | C38: b tâm | D38: 46174 | E38: =VLOOKUP($C38,xe!$A:$B,2,0) -> 50H-70216 | F38: =VLOOKUP($B38,ma!$A:$B,2,0) -> BHX NHÀ BÈ | G38: 89023 | H38: 4/6 | K38: 1.8 | L38: 180000 | O38: 1 | P38: =VLOOKUP($B38,ma!$A:$C,3,0) -> 400000 | Q38: 440000 | R38: 0.1
A39: =A38+1 -> 32 | B39: bnb | C39: t anh | D39: 46174 | E39: =VLOOKUP($C39,xe!$A:$B,2,0) -> 50H-54580 | F39: =VLOOKUP($B39,ma!$A:$B,2,0) -> BHX NHÀ BÈ | G39: 89026 | H39: 4/6 | K39: 1.8 | L39: 180000 | O39: 1 | P39: =VLOOKUP($B39,ma!$A:$C,3,0) -> 400000 | Q39: 440000 | R39: 0.1
A40: 1 | B40: ATP | C40: X1 | D40: 46175 | E40: =VLOOKUP($C40,xe!$A:$B,2,0) -> #N/A | F40: =VLOOKUP($B40,ma!$A:$B,2,0) -> AEON TÂN PHÚ | G40: 10680+89233+89240+89235+89236 | H40: 4/6 | J40: UNI | K40: 1.8 | L40: =K40*50000 -> 90000 | O40: 1 | P40: =VLOOKUP($B40,ma!$A:$C,3,0) -> 800000 | Q40: 880000 | R40: 0.1
...

Sheet XE LỚN
D1: KÊ CHI TIẾT XE LỚN
D2: 46141
D3: Tên : | G3: SỐ XE :
F4: #N/A | K4: 2 | L4: 2 | N4: #N/A
A5: STT | B5: Mã | C5: Tên TX | D5: Ngày | E5: Số Xe | F5: Nơi giao | G5: Đổ Dầu | H5: SỐ KM | I5: C.Phí lấy hàng | J5: ghi chú | K5: C.phí tài xế | L5: ghi chú | M5: TÀI | N5: Đơn giá | O5: Thành tiền | P5: LƯƠNG LX
A6: 1 | B6: QXT | C6: L1 THÀNH | D6: 46174 | E6: =VLOOKUP($C6,xe!$A:$B,2,0) -> 50E-648.73 | F6: =VLOOKUP($B6,ma!$A:$B,2,0) -> QUANG XUÂN TRƯỜNG P.GIÁO | N6: =VLOOKUP($B6,ma!$A:$C,3,0) -> 230000 | O6: =M6*N6 -> 0 | P6: =O6*10% -> 0
A7: =A6+1 -> 2 | B7: PMVX | C7: L2 MẾN | D7: 46174 | E7: =VLOOKUP($C7,xe!$A:$B,2,0) -> 50E-654.34 | F7: =VLOOKUP($B7,ma!$A:$B,2,0) -> PHAN MINH VŨ-BIÊN HOÀ XÁ | M7: 13.93 | N7: =VLOOKUP($B7,ma!$A:$C,3,0) -> 238000 | O7: =M7*N7 -> 3315340 | P7: =O7*10% -> 331534
A8: =A7+1 -> 3 | B8: TLX | C8: L3 HOÀ | D8: 46174 | E8: =VLOOKUP($C8,xe!$A:$B,2,0) -> 50E-324,01 | F8: =VLOOKUP($B8,ma!$A:$B,2,0) -> TUẤN LỘC Q7 XÁ | M8: 15.41 | N8: =VLOOKUP($B8,ma!$A:$C,3,0) -> 200000 | O8: =M8*N8 -> 3082000 | P8: =O8*10% -> 308200
A9: =A8+1 -> 4 | B9: Q6X | C9: L4 QUẠY | D9: 46174 | E9: =VLOOKUP($C9,xe!$A:$B,2,0) -> 50H-87055 | F9: =VLOOKUP($B9,ma!$A:$B,2,0) -> PHẠM ANH QUẬN 6 XÁ | M9: 13.8 | N9: =VLOOKUP($B9,ma!$A:$C,3,0) -> 200000 | O9: =M9*N9 -> 2760000 | P9: =O9*10% -> 276000
A10: =A9+1 -> 5 | B10: TLP | C10: L7 KHANG | D10: 46174 | E10: =VLOOKUP($C10,xe!$A:$B,2,0) -> 50H-66347 | F10: =VLOOKUP($B10,ma!$A:$B,2,0) -> TUẤN LỘC Q7 PALLET | M10: 11.15 | N10: =VLOOKUP($B10,ma!$A:$C,3,0) -> 200000 | O10: =M10*N10 -> 2230000 | P10: =O10*10% -> 223000
A11: =A10+1 -> 6 | B11: q8x | C11: L1 THÀNH | D11: 46175 | E11: =VLOOKUP($C11,xe!$A:$B,2,0) -> 50E-648.73 | F11: =VLOOKUP($B11,ma!$A:$B,2,0) -> QUẬN 8 XÁ | M11: 9.12 | N11: =VLOOKUP($B11,ma!$A:$C,3,0) -> 200000 | O11: =M11*N11 -> 1824000 | P11: =O11*10% -> 182400
A12: =A11+1 -> 7 | B12: Q9X | C12: l2 mến | D12: 46175 | E12: =VLOOKUP($C12,xe!$A:$B,2,0) -> 50E-654.34 | F12: =VLOOKUP($B12,ma!$A:$B,2,0) -> QUẬN 9 XÁ | M12: 14.47 | N12: =VLOOKUP($B12,ma!$A:$C,3,0) -> 200000 | O12: =M12*N12 -> 2894000 | P12: =O12*10% -> 289400
A13: =A12+1 -> 8 | B13: Q9X | C13: L3 HOÀ | D13: 46175 | E13: =VLOOKUP($C13,xe!$A:$B,2,0) -> 50E-324,01 | F13: =VLOOKUP($B13,ma!$A:$B,2,0) -> QUẬN 9 XÁ | M13: 13.94 | N13: =VLOOKUP($B13,ma!$A:$C,3,0) -> 200000 | O13: =M13*N13 -> 2788000 | P13: =O13*10% -> 278800
A14: =A13+1 -> 9 | B14: CLUNI | C14: L3 HOÀ | D14: 46175 | E14: =VLOOKUP($C14,xe!$A:$B,2,0) -> 50E-324,01 | F14: =VLOOKUP($B14,ma!$A:$B,2,0) -> CALOFIC - UNI ( xe lớn ) | M14: 1 | N14: =VLOOKUP($B14,ma!$A:$C,3,0) -> 400000 | O14: =M14*N14 -> 400000 | P14: 100000
A15: =A14+1 -> 10 | B15: Q6P | C15: L4 QUẠY | D15: 46175 | E15: =VLOOKUP($C15,xe!$A:$B,2,0) -> 50H-87055 | F15: =VLOOKUP($B15,ma!$A:$B,2,0) -> PHẠM ANH QUẬN 6 PALLET | M15: 12.71 | N15: =VLOOKUP($B15,ma!$A:$C,3,0) -> 200000 | O15: =M15*N15 -> 2542000 | P15: =O15*10% -> 254200
A16: =A15+1 -> 11 | B16: TLP | C16: L6 PHƯƠNG | D16: 46175 | E16: =VLOOKUP($C16,xe!$A:$B,2,0) -> 50H-75206 | F16: =VLOOKUP($B16,ma!$A:$B,2,0) -> TUẤN LỘC Q7 PALLET | M16: 1.63 | N16: =VLOOKUP($B16,ma!$A:$C,3,0) -> 200000 | O16: =M16*N16 -> 326000 | P16: =O16*10% -> 32600
A17: =A16+1 -> 12 | B17: PMVP | C17: L6 PHƯƠNG | D17: 46175 | E17: =VLOOKUP($C17,xe!$A:$B,2,0) -> 50H-75206 | F17: =VLOOKUP($B17,ma!$A:$B,2,0) -> PHAN MINH VŨ-BIÊN HOÀ PALLET | M17: 13.72 | N17: =VLOOKUP($B17,ma!$A:$C,3,0) -> 238000 | O17: =M17*N17 -> 3265360 | P17: =O17*10% -> 326536
A18: =A17+1 -> 13 | B18: Q9X | C18: L7 KHANG | D18: 46175 | E18: =VLOOKUP($C18,xe!$A:$B,2,0) -> 50H-66347 | F18: =VLOOKUP($B18,ma!$A:$B,2,0) -> QUẬN 9 XÁ | M18: 14.46 | N18: =VLOOKUP($B18,ma!$A:$C,3,0) -> 200000 | O18: =M18*N18 -> 2892000 | P18: =O18*10% -> 289200
A19: =A18+1 -> 14 | B19: TLP | C19: L7 KHANG | D19: 46175 | E19: =VLOOKUP($C19,xe!$A:$B,2,0) -> 50H-66347 | F19: =VLOOKUP($B19,ma!$A:$B,2,0) -> TUẤN LỘC Q7 PALLET | M19: 13.46 | N19: =VLOOKUP($B19,ma!$A:$C,3,0) -> 200000 | O19: =M19*N19 -> 2692000 | P19: =O19*10% -> 269200
A20: =A19+1 -> 15 | B20: Q9P | C20: L1 THÀNH | D20: 46176 | E20: =VLOOKUP($C20,xe!$A:$B,2,0) -> 50E-648.73 | F20: =VLOOKUP($B20,ma!$A:$B,2,0) -> QUẬN 9 PALLET | M20: 10.66 | N20: =VLOOKUP($B20,ma!$A:$C,3,0) -> 200000 | O20: =M20*N20 -> 2132000 | P20: =O20*10% -> 213200
A21: =A20+1 -> 16 | B21: Q6P | C21: l2 mến | D21: 46176 | E21: =VLOOKUP($C21,xe!$A:$B,2,0) -> 50E-654.34 | F21: =VLOOKUP($B21,ma!$A:$B,2,0) -> PHẠM ANH QUẬN 6 PALLET | M21: 13.51 | N21: =VLOOKUP($B21,ma!$A:$C,3,0) -> 200000 | O21: =M21*N21 -> 2702000 | P21: =O21*10% -> 270200
A22: =A21+1 -> 17 | B22: Q8P | C22: L3 HOÀ | D22: 46176 | E22: =VLOOKUP($C22,xe!$A:$B,2,0) -> 50E-324,01 | F22: =VLOOKUP($B22,ma!$A:$B,2,0) -> QUẬN 8 PALLET | M22: 12.35 | N22: =VLOOKUP($B22,ma!$A:$C,3,0) -> 200000 | O22: =M22*N22 -> 2470000 | P22: =O22*10% -> 247000
A23: =A22+1 -> 18 | B23: Q8P | C23: L3 HOÀ | D23: 46176 | E23: =VLOOKUP($C23,xe!$A:$B,2,0) -> 50E-324,01 | F23: =VLOOKUP($B23,ma!$A:$B,2,0) -> QUẬN 8 PALLET | M23: 13.33 | N23: =VLOOKUP($B23,ma!$A:$C,3,0) -> 200000 | O23: =M23*N23 -> 2666000 | P23: =O23*10% -> 266600
A24: =A23+1 -> 19 | B24: Q9X | C24: L4 QUẠY | D24: 46176 | E24: =VLOOKUP($C24,xe!$A:$B,2,0) -> 50H-87055 | F24: =VLOOKUP($B24,ma!$A:$B,2,0) -> QUẬN 9 XÁ | M24: 13.94 | N24: =VLOOKUP($B24,ma!$A:$C,3,0) -> 200000 | O24: =M24*N24 -> 2788000 | P24: =O24*10% -> 278800
A25: =A24+1 -> 20 | B25: TLP | C25: L5 MINH | D25: 46176 | E25: =VLOOKUP($C25,xe!$A:$B,2,0) -> 50E-757,74 | F25: =VLOOKUP($B25,ma!$A:$B,2,0) -> TUẤN LỘC Q7 PALLET | M25: 12.31 | N25: =VLOOKUP($B25,ma!$A:$C,3,0) -> 200000 | O25: =M25*N25 -> 2462000 | P25: =O25*10% -> 246200
A26: =A25+1 -> 21 | B26: TLP | C26: L6 PHƯƠNG | D26: 46176 | E26: =VLOOKUP($C26,xe!$A:$B,2,0) -> 50H-75206 | F26: =VLOOKUP($B26,ma!$A:$B,2,0) -> TUẤN LỘC Q7 PALLET | M26: 11.29 | N26: =VLOOKUP($B26,ma!$A:$C,3,0) -> 200000 | O26: =M26*N26 -> 2258000 | P26: =O26*10% -> 225800
... A33: =A32+1 -> 28 | B33: Q6P | C33: L5 MINH | D33: 46177 | E33: =VLOOKUP($C33,xe!$A:$B,2,0) -> 50E-757,74 | F33: =VLOOKUP($B33,ma!$A:$B,2,0) -> PHẠM ANH QUẬN 6 PALLET | M33: 13.65 | N33: =VLOOKUP($B33,ma!$A:$C,3,0) -> 200000 | O33: =M33*N33 -> 2730000 | P33: =O33*10% -> 273000
A34: =A33+1 -> 29 | B34: NE7 | C34: L6 PHƯƠNG | D34: 46177 | E34: =VLOOKUP($C34,xe!$A:$B,2,0) -> 50H-75206 | F34: =VLOOKUP($B34,ma!$A:$B,2,0) -> NESTLE 7-10 | N34: =VLOOKUP($B34,ma!$A:$C,3,0) -> 393000 | O34: =M34*N34 -> 0 | P34: =O34*10% -> 0
A35: =A34+1 -> 30 | B35: Q8P | C35: L7 KHANG | D35: 46177 | E35: =VLOOKUP($C35,xe!$A:$B,2,0) -> 50H-66347 | F35: =VLOOKUP($B35,ma!$A:$B,2,0) -> QUẬN 8 PALLET | M35: 15.76 | N35: =VLOOKUP($B35,ma!$A:$C,3,0) -> 200000 | O35: =M35*N35 -> 3152000 | P35: =O35*10% -> 315200
A36: =A35+1 -> 31 | B36: cluni | C36: L7 KHANG | D36: 46177 | E36: =VLOOKUP($C36,xe!$A:$B,2,0) -> 50H-66347 | F36: =VLOOKUP($B36,ma!$A:$B,2,0) -> CALOFIC - UNI ( xe lớn ) | M36: 1 | N36: =VLOOKUP($B36,ma!$A:$C,3,0) -> 400000 | O36: =M36*N36 -> 400000 | P36: 100000
A37: =A36+1 -> 32 | B37: ajlh | C37: L3 HOÀ | D37: 46177 | E37: =VLOOKUP($C37,xe!$A:$B,2,0) -> 50E-324,01 | F37: =VLOOKUP($B37,ma!$A:$B,2,0) -> AJ LONG HẬU | M37: 1 | N37: =VLOOKUP($B37,ma!$A:$C,3,0) -> 600000 | O37: =M37*N37 -> 600000 | P37: 100000
A38: =A37+1 -> 33 | B38: NDNA | C38: L1 THÀNH | D38: 46178 | E38: =VLOOKUP($C38,xe!$A:$B,2,0) -> 50E-648.73 | F38: =VLOOKUP($B38,ma!$A:$B,2,0) -> NDFC - NAIC BẾN LỨC | M38: 1 | N38: =VLOOKUP($B38,ma!$A:$C,3,0) -> 2400000 | O38: =M38*N38 -> 2400000 | P38: =O38*10% -> 240000
A39: =A38+1 -> 34 | B39: TLP | C39: L3 HOÀ | D39: 46178 | E39: =VLOOKUP($C39,xe!$A:$B,2,0) -> 50E-324,01 | F39: =VLOOKUP($B39,ma!$A:$B,2,0) -> TUẤN LỘC Q7 PALLET | M39: 13.58 | N39: =VLOOKUP($B39,ma!$A:$C,3,0) -> 200000 | O39: =M39*N39 -> 2716000 | P39: =O39*10% -> 271600
A40: =A39+1 -> 35 | B40: TLP | C40: L3 HOÀ | D40: 46178 | E40: =VLOOKUP($C40,xe!$A:$B,2,0) -> 50E-324,01 | F40: =VLOOKUP($B40,ma!$A:$B,2,0) -> TUẤN LỘC Q7 PALLET | M40: 12.7 | N40: =VLOOKUP($B40,ma!$A:$C,3,0) -> 200000 | O40: =M40*N40 -> 2540000 | P40: =O40*10% -> 254000
A41: =A40+1 -> 36 | B41: NDNA | C41: L4 QUẠY | D41: 46178 | E41: =VLOOKUP($C41,xe!$A:$B,2,0) -> 50H-87055 | F41: =VLOOKUP($B41,ma!$A:$B,2,0) -> NDFC - NAIC BẾN LỨC | M41: 1 | N41: =VLOOKUP($B41,ma!$A:$C,3,0) -> 2400000 | O41: =M41*N41 -> 2400000 | P41: =O41*10% -> 240000
A42: =A41+1 -> 37 | B42: NDNA | C42: L5 MINH | D42: 46178 | E42: =VLOOKUP($C42,xe!$A:$B,2,0) -> 50E-757,74 | F42: =VLOOKUP($B42,ma!$A:$B,2,0) -> NDFC - NAIC BẾN LỨC | M42: 1 | N42: =VLOOKUP($B42,ma!$A:$C,3,0) -> 2400000 | O42: =M42*N42 -> 2400000 | P42: =O42*10% -> 240000
A43: =A42+1 -> 38 | B43: MXD | C43: L5 MINH | D43: 46178 | E43: =VLOOKUP($C43,xe!$A:$B,2,0) -> 50E-757,74 | F43: =VLOOKUP($B43,ma!$A:$B,2,0) -> MAXIDI ĐỒNG NAI | M43: 12.86 | N43: =VLOOKUP($B43,ma!$A:$C,3,0) -> 238000 | O43: =M43*N43 -> 3060680 | P43: =O43*10% -> 306068
A44: =A43+1 -> 39 | B44: NDNA | C44: L6 PHƯƠNG | D44: 46178 | E44: =VLOOKUP($C44,xe!$A:$B,2,0) -> 50H-75206 | F44: =VLOOKUP($B44,ma!$A:$B,2,0) -> NDFC - NAIC BẾN LỨC | M44: 1 | N44: =VLOOKUP($B44,ma!$A:$C,3,0) -> 2400000 | O44: =M44*N44 -> 2400000 | P44: =O44*10% -> 240000
A45: =A44+1 -> 40 | B45: Q6P | C45: L6 PHƯƠNG | D45: 46178 | E45: =VLOOKUP($C45,xe!$A:$B,2,0) -> 50H-75206 | F45: =VLOOKUP($B45,ma!$A:$B,2,0) -> PHẠM ANH QUẬN 6 PALLET | M45: 11.81 | N45: =VLOOKUP($B45,ma!$A:$C,3,0) -> 200000 | O45: =M45*N45 -> 2362000 | P45: =O45*10% -> 236200
A46: =A45+1 -> 41 | B46: Q8P | C46: L7 KHANG | D46: 46178 | E46: =VLOOKUP($C46,xe!$A:$B,2,0) -> 50H-66347 | F46: =VLOOKUP($B46,ma!$A:$B,2,0) -> QUẬN 8 PALLET | M46: 12.77 | N46: =VLOOKUP($B46,ma!$A:$C,3,0) -> 200000 | O46: =M46*N46 -> 2554000 | P46: =O46*10% -> 255400
...

Sheet TRUNG CHUYỂN
D1: KÊ CHI TIẾT XE LỚN | Q1: PHƯƠNG | R1: 50H-75206
D2: 46141 | Q2: ÂN | R2: 50H-55294
D3: Tên : | G3: SỐ XE : | Q3: HOÀNG | R3: 50H-55129
F4: #N/A | K4: 2 | M4: 2 | O4: #N/A | Q4: HẢI | R4: 50H-69717
A5: STT | B5: Mã | C5: Tên TX | D5: Ngày | E5: Số Xe | F5: Nơi giao | G5: Đổ Dầu | H5: SỐ KM | I5: C.phí tài xế | J5: ghi chú | K5: Cầu đường | L5: C.phí tài xế | M5: ghi chú | N5: TÀI | O5: Đơn giá | P5: Thành tiền | Q5: LƯƠNG LX
A6: 1 | B6: MCC | C6: L8 NHANH | D6: 46174 | E6: =VLOOKUP($C6,xe!$A:$B,2,0) -> 50E-758,73 | F6: =VLOOKUP($B6,ma!$A:$B,2,0) -> Chuyển hàng MCC | I6: 40000 | J6: CLF | N6: 4 | O6: =VLOOKUP($B6,ma!$A:$C,3,0) -> 414000 | P6: =N6*O6 -> 1656000 | Q6: =N6*50000 -> 200000
A7: =A6+1 -> 2 | B7: NDFC | C7: L9 ÂN | D7: 46174 | E7: =VLOOKUP($C7,xe!$A:$B,2,0) -> 50H-55294 | F7: =VLOOKUP($B7,ma!$A:$B,2,0) -> Chuyển Hàng ndfc | N7: 3 | O7: =VLOOKUP($B7,ma!$A:$C,3,0) -> 410000 | P7: =N7*O7 -> 1230000 | Q7: =N7*50000 -> 150000
A8: =A7+1 -> 3 | B8: CALO | C8: L10 HOÀNG | D8: 46174 | E8: =VLOOKUP($C8,xe!$A:$B,2,0) -> 50H-55129 | F8: =VLOOKUP($B8,ma!$A:$B,2,0) -> Chuyển hàng Calofic | N8: 11 | O8: =VLOOKUP($B8,ma!$A:$C,3,0) -> 180000 | P8: =N8*O8 -> 1980000 | Q8: =N8*50000 -> 550000
A9: =A8+1 -> 4 | B9: CALO | C9: L11 HẢI | D9: 46174 | E9: =VLOOKUP($C9,xe!$A:$B,2,0) -> 50H-69717 | F9: =VLOOKUP($B9,ma!$A:$B,2,0) -> Chuyển hàng Calofic | N9: 9 | O9: =VLOOKUP($B9,ma!$A:$C,3,0) -> 180000 | P9: =N9*O9 -> 1620000 | Q9: =N9*50000 -> 450000
A10: =A9+1 -> 5 | B10: MCC | C10: L8 NHANH | D10: 46175 | E10: =VLOOKUP($C10,xe!$A:$B,2,0) -> 50E-758,73 | F10: =VLOOKUP($B10,ma!$A:$B,2,0) -> Chuyển hàng MCC | I10: 20000 | J10: CLF | N10: 4 | O10: =VLOOKUP($B10,ma!$A:$C,3,0) -> 414000 | P10: =N10*O10 -> 1656000 | Q10: =N10*50000 -> 200000
A11: =A10+1 -> 6 | B11: NDFC | C11: L9 ÂN | D11: 46175 | E11: =VLOOKUP($C11,xe!$A:$B,2,0) -> 50H-55294 | F11: =VLOOKUP($B11,ma!$A:$B,2,0) -> Chuyển Hàng ndfc | N11: 4 | O11: =VLOOKUP($B11,ma!$A:$C,3,0) -> 410000 | P11: =N11*O11 -> 1640000 | Q11: =N11*50000 -> 200000
A12: =A11+1 -> 7 | B12: CALO | C12: L10 HOÀNG | D12: 46175 | E12: =VLOOKUP($C12,xe!$A:$B,2,0) -> 50H-55129 | F12: =VLOOKUP($B12,ma!$A:$B,2,0) -> Chuyển hàng Calofic | N12: 8 | O12: =VLOOKUP($B12,ma!$A:$C,3,0) -> 180000 | P12: =N12*O12 -> 1440000 | Q12: =N12*50000 -> 400000
A13: =A12+1 -> 8 | B13: CALO | C13: L11 HẢI | D13: 46175 | E13: =VLOOKUP($C13,xe!$A:$B,2,0) -> 50H-69717 | F13: =VLOOKUP($B13,ma!$A:$B,2,0) -> Chuyển hàng Calofic | N13: 10 | O13: =VLOOKUP($B13,ma!$A:$C,3,0) -> 180000 | P13: =N13*O13 -> 1800000 | Q13: =N13*50000 -> 500000
A14: =A13+1 -> 9 | B14: MCC | C14: L8 NHANH | D14: 46176 | E14: =VLOOKUP($C14,xe!$A:$B,2,0) -> 50E-758,73 | F14: =VLOOKUP($B14,ma!$A:$B,2,0) -> Chuyển hàng MCC | I14: 20000 | J14: CLF | N14: 4 | O14: =VLOOKUP($B14,ma!$A:$C,3,0) -> 414000 | P14: =N14*O14 -> 1656000 | Q14: =N14*50000 -> 200000
A15: =A14+1 -> 10 | B15: NDFC | C15: L9 ÂN | D15: 46176 | E15: =VLOOKUP($C15,xe!$A:$B,2,0) -> 50H-55294 | F15: =VLOOKUP($B15,ma!$A:$B,2,0) -> Chuyển Hàng ndfc | N15: 4 | O15: =VLOOKUP($B15,ma!$A:$C,3,0) -> 410000 | P15: =N15*O15 -> 1640000 | Q15: =N15*50000 -> 200000
A16: =A15+1 -> 11 | B16: CALO | C16: L10 HOÀNG | D16: 46176 | E16: =VLOOKUP($C16,xe!$A:$B,2,0) -> 50H-55129 | F16: =VLOOKUP($B16,ma!$A:$B,2,0) -> Chuyển hàng Calofic | N16: 8 | O16: =VLOOKUP($B16,ma!$A:$C,3,0) -> 180000 | P16: =N16*O16 -> 1440000 | Q16: =N16*50000 -> 400000
A17: =A16+1 -> 12 | B17: CALO | C17: L11 HẢI | D17: 46176 | E17: =VLOOKUP($C17,xe!$A:$B,2,0) -> 50H-69717 | F17: =VLOOKUP($B17,ma!$A:$B,2,0) -> Chuyển hàng Calofic | N17: 7 | O17: =VLOOKUP($B17,ma!$A:$C,3,0) -> 180000 | P17: =N17*O17 -> 1260000 | Q17: =N17*50000 -> 350000
A18: =A17+1 -> 13 | B18: MCC | C18: L8 NHANH | D18: 46177 | E18: =VLOOKUP($C18,xe!$A:$B,2,0) -> 50E-758,73 | F18: =VLOOKUP($B18,ma!$A:$B,2,0) -> Chuyển hàng MCC | I18: 20000 | J18: CLF | N18: 4 | O18: =VLOOKUP($B18,ma!$A:$C,3,0) -> 414000 | P18: =N18*O18 -> 1656000 | Q18: =N18*50000 -> 200000
A19: =A18+1 -> 14 | B19: NDFC | C19: L9 ÂN | D19: 46177 | E19: =VLOOKUP($C19,xe!$A:$B,2,0) -> 50H-55294 | F19: =VLOOKUP($B19,ma!$A:$B,2,0) -> Chuyển Hàng ndfc | N19: 3 | O19: =VLOOKUP($B19,ma!$A:$C,3,0) -> 410000 | P19: =N19*O19 -> 1230000 | Q19: =N19*50000 -> 150000
A20: =A19+1 -> 15 | B20: CALO | C20: L10 HOÀNG | D20: 46177 | E20: =VLOOKUP($C20,xe!$A:$B,2,0) -> 50H-55129 | F20: =VLOOKUP($B20,ma!$A:$B,2,0) -> Chuyển hàng Calofic | N20: 10 | O20: =VLOOKUP($B20,ma!$A:$C,3,0) -> 180000 | P20: =N20*O20 -> 1800000 | Q20: =N20*50000 -> 500000
A21: =A20+1 -> 16 | B21: CALO | C21: L11 HẢI | D21: 46177 | E21: =VLOOKUP($C21,xe!$A:$B,2,0) -> 50H-69717 | F21: =VLOOKUP($B21,ma!$A:$B,2,0) -> Chuyển hàng Calofic | N21: 10 | O21: =VLOOKUP($B21,ma!$A:$C,3,0) -> 180000 | P21: =N21*O21 -> 1800000 | Q21: =N21*50000 -> 500000
A22: =A21+1 -> 17 | B22: MCC | C22: L8 NHANH | D22: 46178 | E22: =VLOOKUP($C22,xe!$A:$B,2,0) -> 50E-758,73 | F22: =VLOOKUP($B22,ma!$A:$B,2,0) -> Chuyển hàng MCC | N22: 4 | O22: =VLOOKUP($B22,ma!$A:$C,3,0) -> 414000 | P22: =N22*O22 -> 1656000 | Q22: =N22*50000 -> 200000
A23: =A22+1 -> 18 | B23: NDFC | C23: L9 ÂN | D23: 46178 | E23: =VLOOKUP($C23,xe!$A:$B,2,0) -> 50H-55294 | F23: =VLOOKUP($B23,ma!$A:$B,2,0) -> Chuyển Hàng ndfc | N23: 3 | O23: =VLOOKUP($B23,ma!$A:$C,3,0) -> 410000 | P23: =N23*O23 -> 1230000 | Q23: =N23*50000 -> 150000
A24: =A23+1 -> 19 | B24: CALO | C24: L10 HOÀNG | D24: 46178 | E24: =VLOOKUP($C24,xe!$A:$B,2,0) -> 50H-55129 | F24: =VLOOKUP($B24,ma!$A:$B,2,0) -> Chuyển hàng Calofic | N24: 10 | O24: =VLOOKUP($B24,ma!$A:$C,3,0) -> 180000 | P24: =N24*O24 -> 1800000 | Q24: =N24*50000 -> 500000
A25: =A24+1 -> 20 | B25: CALO | C25: L11 HẢI | D25: 46178 | E25: =VLOOKUP($C25,xe!$A:$B,2,0) -> 50H-69717 | F25: =VLOOKUP($B25,ma!$A:$B,2,0) -> Chuyển hàng Calofic | N25: 6 | O25: =VLOOKUP($B25,ma!$A:$C,3,0) -> 180000 | P25: =N25*O25 -> 1080000 | Q25: =N25*50000 -> 300000
A26: =A25+1 -> 21 | B26: MCC | C26: L8 NHANH | D26: 46179 | E26: =VLOOKUP($C26,xe!$A:$B,2,0) -> 50E-758,73 | F26: =VLOOKUP($B26,ma!$A:$B,2,0) -> Chuyển hàng MCC | N26: 5 | O26: =VLOOKUP($B26,ma!$A:$C,3,0) -> 414000 | P26: =N26*O26 -> 2070000 | Q26: =N26*50000 -> 250000
A27: =A26+1 -> 22 | B27: NDFC | C27: L9 ÂN | D27: 46179 | E27: =VLOOKUP($C27,xe!$A:$B,2,0) -> 50H-55294 | F27: =VLOOKUP($B27,ma!$A:$B,2,0) -> Chuyển Hàng ndfc | N27: 2 | O27: =VLOOKUP($B27,ma!$A:$C,3,0) -> 410000 | P27: =N27*O27 -> 820000 | Q27: =N27*50000 -> 100000
A28: =A27+1 -> 23 | B28: CALO | C28: L10 HOÀNG | D28: 46179 | E28: =VLOOKUP($C28,xe!$A:$B,2,0) -> 50H-55129 | F28: =VLOOKUP($B28,ma!$A:$B,2,0) -> Chuyển hàng Calofic | N28: 6 | O28: =VLOOKUP($B28,ma!$A:$C,3,0) -> 180000 | P28: =N28*O28 -> 1080000 | Q28: =N28*50000 -> 300000
A29: =A28+1 -> 24 | B29: CALO | C29: L11 HẢI | D29: 46179 | E29: =VLOOKUP($C29,xe!$A:$B,2,0) -> 50H-69717 | F29: =VLOOKUP($B29,ma!$A:$B,2,0) -> Chuyển hàng Calofic | N29: 7 | O29: =VLOOKUP($B29,ma!$A:$C,3,0) -> 180000 | P29: =N29*O29 -> 1260000 | Q29: =N29*50000 -> 350000
A30: =A29+1 -> 25 | B30: MCC | C30: L8 NHANH | D30: 46181 | E30: =VLOOKUP($C30,xe!$A:$B,2,0) -> 50E-758,73 | F30: =VLOOKUP($B30,ma!$A:$B,2,0) -> Chuyển hàng MCC | I30: 20000 | J30: CLF | N30: 3 | O30: =VLOOKUP($B30,ma!$A:$C,3,0) -> 414000 | P30: =N30*O30 -> 1242000 | Q30: =N30*50000 -> 150000
A31: =A30+1 -> 26 | B31: NDFC | C31: L9 ÂN | D31: 46181 | E31: =VLOOKUP($C31,xe!$A:$B,2,0) -> 50H-55294 | F31: =VLOOKUP($B31,ma!$A:$B,2,0) -> Chuyển Hàng ndfc | N31: 2 | O31: =VLOOKUP($B31,ma!$A:$C,3,0) -> 410000 | P31: =N31*O31 -> 820000 | Q31: =N31*50000 -> 100000
A32: =A31+1 -> 27 | B32: CALO | C32: L10 HOÀNG | D32: 46181 | E32: =VLOOKUP($C32,xe!$A:$B,2,0) -> 50H-55129 | F32: =VLOOKUP($B32,ma!$A:$B,2,0) -> Chuyển hàng Calofic | N32: 7 | O32: =VLOOKUP($B32,ma!$A:$C,3,0) -> 180000 | P32: =N32*O32 -> 1260000 | Q32: =N32*50000 -> 350000
A33: =A32+1 -> 28 | B33: MCC | C33: L8 NHANH | D33: 46182 | E33: =VLOOKUP($C33,xe!$A:$B,2,0) -> 50E-758,73 | F33: =VLOOKUP($B33,ma!$A:$B,2,0) -> Chuyển hàng MCC | I33: 20000 | J33: CLF | N33: 4 | O33: =VLOOKUP($B33,ma!$A:$C,3,0) -> 414000 | P33: =N33*O33 -> 1656000 | Q33: =N33*50000 -> 200000
A34: =A33+1 -> 29 | B34: NDFC | C34: L9 ÂN | D34: 46182 | E34: =VLOOKUP($C34,xe!$A:$B,2,0) -> 50H-55294 | F34: =VLOOKUP($B34,ma!$A:$B,2,0) -> Chuyển Hàng ndfc | N34: 4 | O34: =VLOOKUP($B34,ma!$A:$C,3,0) -> 410000 | P34: =N34*O34 -> 1640000 | Q34: =N34*50000 -> 200000
A35: =A34+1 -> 30 | B35: CALO | C35: L10 HOÀNG | D35: 46182 | E35: =VLOOKUP($C35,xe!$A:$B,2,0) -> 50H-55129 | F35: =VLOOKUP($B35,ma!$A:$B,2,0) -> Chuyển hàng Calofic | N35: 8 | O35: =VLOOKUP($B35,ma!$A:$C,3,0) -> 180000 | P35: =N35*O35 -> 1440000 | Q35: =N35*50000 -> 400000
A36: =A35+1 -> 31 | B36: CALO | C36: L11 HẢI | D36: 46182 | E36: =VLOOKUP($C36,xe!$A:$B,2,0) -> 50H-69717 | F36: =VLOOKUP($B36,ma!$A:$B,2,0) -> Chuyển hàng Calofic | N36: 7 | O36: =VLOOKUP($B36,ma!$A:$C,3,0) -> 180000 | P36: =N36*O36 -> 1260000 | Q36: =N36*50000 -> 350000
A37: =A36+1 -> 32 | B37: MCC | C37: L8 NHANH | D37: 46183 | E37: =VLOOKUP($C37,xe!$A:$B,2,0) -> 50E-758,73 | F37: =VLOOKUP($B37,ma!$A:$B,2,0) -> Chuyển hàng MCC | I37: 20000 | J37: CLF | N37: 3 | O37: =VLOOKUP($B37,ma!$A:$C,3,0) -> 414000 | P37: =N37*O37 -> 1242000 | Q37: =N37*50000 -> 150000
A38: =A37+1 -> 33 | B38: NDFC | C38: L9 ÂN | D38: 46183 | E38: =VLOOKUP($C38,xe!$A:$B,2,0) -> 50H-55294 | F38: =VLOOKUP($B38,ma!$A:$B,2,0) -> Chuyển Hàng ndfc | N38: 4 | O38: =VLOOKUP($B38,ma!$A:$C,3,0) -> 410000 | P38: =N38*O38 -> 1640000 | Q38: =N38*50000 -> 200000
A39: =A38+1 -> 34 | B39: CALO | C39: L10 HOÀNG | D39: 46183 | E39: =VLOOKUP($C39,xe!$A:$B,2,0) -> 50H-55129 | F39: =VLOOKUP($B39,ma!$A:$B,2,0) -> Chuyển hàng Calofic | N39: 9 | O39: =VLOOKUP($B39,ma!$A:$C,3,0) -> 180000 | P39: =N39*O39 -> 1620000 | Q39: =N39*50000 -> 450000
A40: =A39+1 -> 35 | B40: CALO | C40: L11 HẢI | D40: 46183 | E40: =VLOOKUP($C40,xe!$A:$B,2,0) -> 50H-69717 | F40: =VLOOKUP($B40,ma!$A:$B,2,0) -> Chuyển hàng Calofic | N40: 3 | O40: =VLOOKUP($B40,ma!$A:$C,3,0) -> 180000 | P40: =N40*O40 -> 540000 | Q40: =N40*50000 -> 150000
...
